2025-06-11 20:43:01,784 [INFO] C:\Users\caval\OneDrive\Desktop\projeto-portal-v2\apps\participacao\views\participation.py changed, reloading.
2025-06-11 20:43:19,882 [INFO] C:\Users\caval\OneDrive\Desktop\projeto-portal-v2\apps\participacao\views\participation.py changed, reloading.
2025-06-11 20:47:36,886 [INFO] C:\Users\caval\OneDrive\Desktop\projeto-portal-v2\apps\participacao\models\__init__.py changed, reloading.
2025-06-11 20:48:12,593 [INFO] C:\Users\caval\OneDrive\Desktop\projeto-portal-v2\apps\participacao\views\participation.py changed, reloading.
2025-06-11 20:52:10,988 [INFO] C:\Users\caval\OneDrive\Desktop\projeto-portal-v2\apps\participacao\views\participation.py changed, reloading.
2025-06-11 20:56:13,545 [INFO] C:\Users\caval\OneDrive\Desktop\projeto-portal-v2\apps\participacao\views\participation.py changed, reloading.
2025-06-11 20:59:31,514 [INFO] C:\Users\caval\OneDrive\Desktop\projeto-portal-v2\apps\participacao\views\participation.py changed, reloading.
2025-06-11 21:01:32,305 [INFO] C:\Users\caval\OneDrive\Desktop\projeto-portal-v2\apps\participacao\views\participation.py changed, reloading.
2025-06-11 21:03:22,589 [INFO] C:\Users\caval\OneDrive\Desktop\projeto-portal-v2\apps\participacao\views\participation.py changed, reloading.
2025-06-11 21:29:36,349 [INFO] C:\Users\caval\OneDrive\Desktop\projeto-portal-v2\apps\participacao\views\participation.py changed, reloading.
2025-06-11 21:34:37,053 [INFO] C:\Users\caval\OneDrive\Desktop\projeto-portal-v2\apps\participacao\views\participation.py changed, reloading.
2025-06-11 21:48:27,198 [INFO] C:\Users\caval\OneDrive\Desktop\projeto-portal-v2\Projeto_Portal_v2\settings.py changed, reloading.
2025-06-11 21:58:06,036 [INFO] C:\Users\caval\OneDrive\Desktop\projeto-portal-v2\Projeto_Portal_v2\settings.py changed, reloading.
2025-06-11 22:03:05,629 [INFO] C:\Users\caval\OneDrive\Desktop\projeto-portal-v2\Projeto_Portal_v2\wsgi.py changed, reloading.
2025-06-11 22:03:21,370 [WARNING] Not Found: /
2025-06-11 22:03:21,692 [WARNING] Not Found: /favicon.ico
2025-06-11 22:03:38,710 [WARNING] Not Found: /
2025-06-11 22:07:03,856 [INFO] C:\Users\caval\OneDrive\Desktop\projeto-portal-v2\Projeto_Portal_v2\urls.py changed, reloading.
2025-06-11 22:08:47,723 [INFO] C:\Users\caval\OneDrive\Desktop\projeto-portal-v2\Projeto_Portal_v2\urls.py changed, reloading.
2025-06-11 22:09:38,131 [INFO] C:\Users\caval\OneDrive\Desktop\projeto-portal-v2\Projeto_Portal_v2\urls.py changed, reloading.
2025-06-11 22:13:11,978 [ERROR] Erro ao registrar tentativa de login: name 'User' is not defined
2025-06-11 22:13:13,399 [INFO] Usuário admin acessando página inicial
2025-06-11 22:13:13,723 [ERROR] Internal Server Error: /participacao/
Traceback (most recent call last):
  File "C:\Users\caval\AppData\Local\Programs\Python\Python312\Lib\site-packages\django\core\handlers\exception.py", line 55, in inner
    response = get_response(request)
               ^^^^^^^^^^^^^^^^^^^^^
  File "C:\Users\caval\AppData\Local\Programs\Python\Python312\Lib\site-packages\django\core\handlers\base.py", line 197, in _get_response
    response = wrapped_callback(request, *callback_args, **callback_kwargs)
               ^^^^^^^^^^^^^^^^^^^^^^^^^^^^^^^^^^^^^^^^^^^^^^^^^^^^^^^^^^^^
  File "C:\Users\caval\AppData\Local\Programs\Python\Python312\Lib\site-packages\django\contrib\auth\decorators.py", line 59, in _view_wrapper
    return view_func(request, *args, **kwargs)
           ^^^^^^^^^^^^^^^^^^^^^^^^^^^^^^^^^^^
  File "C:\Users\caval\OneDrive\Desktop\projeto-portal-v2\apps\participacao\views\participation.py", line 80, in index
    setores = Setor.objects.annotate(total_funcionarios=Count('funcionarios')).order_by('nome')
              ^^^^^^^^^^^^^^^^^^^^^^^^^^^^^^^^^^^^^^^^^^^^^^^^^^^^^^^^^^^^^^^^
  File "C:\Users\caval\AppData\Local\Programs\Python\Python312\Lib\site-packages\django\db\models\manager.py", line 87, in manager_method
    return getattr(self.get_queryset(), name)(*args, **kwargs)
           ^^^^^^^^^^^^^^^^^^^^^^^^^^^^^^^^^^^^^^^^^^^^^^^^^^^
  File "C:\Users\caval\AppData\Local\Programs\Python\Python312\Lib\site-packages\django\db\models\query.py", line 1635, in annotate
    return self._annotate(args, kwargs, select=True)
           ^^^^^^^^^^^^^^^^^^^^^^^^^^^^^^^^^^^^^^^^^
  File "C:\Users\caval\AppData\Local\Programs\Python\Python312\Lib\site-packages\django\db\models\query.py", line 1687, in _annotate
    clone.query.add_annotation(
  File "C:\Users\caval\AppData\Local\Programs\Python\Python312\Lib\site-packages\django\db\models\sql\query.py", line 1218, in add_annotation
    annotation = annotation.resolve_expression(self, allow_joins=True, reuse=None)
                 ^^^^^^^^^^^^^^^^^^^^^^^^^^^^^^^^^^^^^^^^^^^^^^^^^^^^^^^^^^^^^^^^^
  File "C:\Users\caval\AppData\Local\Programs\Python\Python312\Lib\site-packages\django\db\models\aggregates.py", line 181, in resolve_expression
    result = super().resolve_expression(*args, **kwargs)
             ^^^^^^^^^^^^^^^^^^^^^^^^^^^^^^^^^^^^^^^^^^^
  File "C:\Users\caval\AppData\Local\Programs\Python\Python312\Lib\site-packages\django\db\models\aggregates.py", line 63, in resolve_expression
    c = super().resolve_expression(query, allow_joins, reuse, summarize)
        ^^^^^^^^^^^^^^^^^^^^^^^^^^^^^^^^^^^^^^^^^^^^^^^^^^^^^^^^^^^^^^^^
  File "C:\Users\caval\AppData\Local\Programs\Python\Python312\Lib\site-packages\django\db\models\expressions.py", line 300, in resolve_expression
    expr.resolve_expression(query, allow_joins, reuse, summarize)
  File "C:\Users\caval\AppData\Local\Programs\Python\Python312\Lib\site-packages\django\db\models\expressions.py", line 902, in resolve_expression
    return query.resolve_ref(self.name, allow_joins, reuse, summarize)
           ^^^^^^^^^^^^^^^^^^^^^^^^^^^^^^^^^^^^^^^^^^^^^^^^^^^^^^^^^^^
  File "C:\Users\caval\AppData\Local\Programs\Python\Python312\Lib\site-packages\django\db\models\sql\query.py", line 2046, in resolve_ref
    join_info = self.setup_joins(
                ^^^^^^^^^^^^^^^^^
  File "C:\Users\caval\AppData\Local\Programs\Python\Python312\Lib\site-packages\django\db\models\sql\query.py", line 1897, in setup_joins
    path, final_field, targets, rest = self.names_to_path(
                                       ^^^^^^^^^^^^^^^^^^^
  File "C:\Users\caval\AppData\Local\Programs\Python\Python312\Lib\site-packages\django\db\models\sql\query.py", line 1802, in names_to_path
    raise FieldError(
django.core.exceptions.FieldError: Cannot resolve keyword 'funcionarios' into field. Choices are: aprovacaosetor, ativo, funcionario, id, nome, recebe_participacao, valor_base
2025-06-11 22:22:42,626 [ERROR] Erro ao registrar tentativa de login: name 'User' is not defined
2025-06-11 22:22:44,382 [WARNING] Falha na tentativa de login: username=admin, IP=127.0.0.1
2025-06-11 22:22:52,312 [ERROR] Erro ao registrar tentativa de login: name 'User' is not defined
2025-06-11 22:22:54,036 [INFO] Usuário admin acessando página inicial
2025-06-11 22:22:54,091 [ERROR] Internal Server Error: /participacao/
Traceback (most recent call last):
  File "C:\Users\caval\AppData\Local\Programs\Python\Python312\Lib\site-packages\django\core\handlers\exception.py", line 55, in inner
    response = get_response(request)
               ^^^^^^^^^^^^^^^^^^^^^
  File "C:\Users\caval\AppData\Local\Programs\Python\Python312\Lib\site-packages\django\core\handlers\base.py", line 197, in _get_response
    response = wrapped_callback(request, *callback_args, **callback_kwargs)
               ^^^^^^^^^^^^^^^^^^^^^^^^^^^^^^^^^^^^^^^^^^^^^^^^^^^^^^^^^^^^
  File "C:\Users\caval\AppData\Local\Programs\Python\Python312\Lib\site-packages\django\contrib\auth\decorators.py", line 59, in _view_wrapper
    return view_func(request, *args, **kwargs)
           ^^^^^^^^^^^^^^^^^^^^^^^^^^^^^^^^^^^
  File "C:\Users\caval\OneDrive\Desktop\projeto-portal-v2\apps\participacao\views\participation.py", line 80, in index
    setores = Setor.objects.annotate(total_funcionarios=Count('funcionarios')).order_by('nome')
              ^^^^^^^^^^^^^^^^^^^^^^^^^^^^^^^^^^^^^^^^^^^^^^^^^^^^^^^^^^^^^^^^
  File "C:\Users\caval\AppData\Local\Programs\Python\Python312\Lib\site-packages\django\db\models\manager.py", line 87, in manager_method
    return getattr(self.get_queryset(), name)(*args, **kwargs)
           ^^^^^^^^^^^^^^^^^^^^^^^^^^^^^^^^^^^^^^^^^^^^^^^^^^^
  File "C:\Users\caval\AppData\Local\Programs\Python\Python312\Lib\site-packages\django\db\models\query.py", line 1635, in annotate
    return self._annotate(args, kwargs, select=True)
           ^^^^^^^^^^^^^^^^^^^^^^^^^^^^^^^^^^^^^^^^^
  File "C:\Users\caval\AppData\Local\Programs\Python\Python312\Lib\site-packages\django\db\models\query.py", line 1687, in _annotate
    clone.query.add_annotation(
  File "C:\Users\caval\AppData\Local\Programs\Python\Python312\Lib\site-packages\django\db\models\sql\query.py", line 1218, in add_annotation
    annotation = annotation.resolve_expression(self, allow_joins=True, reuse=None)
                 ^^^^^^^^^^^^^^^^^^^^^^^^^^^^^^^^^^^^^^^^^^^^^^^^^^^^^^^^^^^^^^^^^
  File "C:\Users\caval\AppData\Local\Programs\Python\Python312\Lib\site-packages\django\db\models\aggregates.py", line 181, in resolve_expression
    result = super().resolve_expression(*args, **kwargs)
             ^^^^^^^^^^^^^^^^^^^^^^^^^^^^^^^^^^^^^^^^^^^
  File "C:\Users\caval\AppData\Local\Programs\Python\Python312\Lib\site-packages\django\db\models\aggregates.py", line 63, in resolve_expression
    c = super().resolve_expression(query, allow_joins, reuse, summarize)
        ^^^^^^^^^^^^^^^^^^^^^^^^^^^^^^^^^^^^^^^^^^^^^^^^^^^^^^^^^^^^^^^^
  File "C:\Users\caval\AppData\Local\Programs\Python\Python312\Lib\site-packages\django\db\models\expressions.py", line 300, in resolve_expression
    expr.resolve_expression(query, allow_joins, reuse, summarize)
  File "C:\Users\caval\AppData\Local\Programs\Python\Python312\Lib\site-packages\django\db\models\expressions.py", line 902, in resolve_expression
    return query.resolve_ref(self.name, allow_joins, reuse, summarize)
           ^^^^^^^^^^^^^^^^^^^^^^^^^^^^^^^^^^^^^^^^^^^^^^^^^^^^^^^^^^^
  File "C:\Users\caval\AppData\Local\Programs\Python\Python312\Lib\site-packages\django\db\models\sql\query.py", line 2046, in resolve_ref
    join_info = self.setup_joins(
                ^^^^^^^^^^^^^^^^^
  File "C:\Users\caval\AppData\Local\Programs\Python\Python312\Lib\site-packages\django\db\models\sql\query.py", line 1897, in setup_joins
    path, final_field, targets, rest = self.names_to_path(
                                       ^^^^^^^^^^^^^^^^^^^
  File "C:\Users\caval\AppData\Local\Programs\Python\Python312\Lib\site-packages\django\db\models\sql\query.py", line 1802, in names_to_path
    raise FieldError(
django.core.exceptions.FieldError: Cannot resolve keyword 'funcionarios' into field. Choices are: aprovacaosetor, ativo, funcionario, id, nome, recebe_participacao, valor_base
2025-06-11 22:27:32,965 [DEBUG] Processando requisição para /participacao/participacao/ - Usuário autenticado: True
2025-06-11 22:27:33,099 [ERROR] Internal Server Error: /participacao/participacao/
Traceback (most recent call last):
  File "C:\Users\caval\AppData\Local\Programs\Python\Python312\Lib\site-packages\django\db\models\fields\related_descriptors.py", line 513, in __get__
    rel_obj = self.related.get_cached_value(instance)
              ^^^^^^^^^^^^^^^^^^^^^^^^^^^^^^^^^^^^^^^
  File "C:\Users\caval\AppData\Local\Programs\Python\Python312\Lib\site-packages\django\db\models\fields\mixins.py", line 37, in get_cached_value
    return instance._state.fields_cache[self.cache_name]
           ~~~~~~~~~~~~~~~~~~~~~~~~~~~~^^^^^^^^^^^^^^^^^
KeyError: 'funcionario'

During handling of the above exception, another exception occurred:

Traceback (most recent call last):
  File "C:\Users\caval\AppData\Local\Programs\Python\Python312\Lib\site-packages\django\db\backends\utils.py", line 105, in _execute
    return self.cursor.execute(sql, params)
           ^^^^^^^^^^^^^^^^^^^^^^^^^^^^^^^^
psycopg2.errors.UndefinedTable: ERRO:  relação "participacao_funcionario" não existe
LINE 1: ...or", "participacao_funcionario"."abono_type" FROM "participa...
                                                             ^


The above exception was the direct cause of the following exception:

Traceback (most recent call last):
  File "C:\Users\caval\AppData\Local\Programs\Python\Python312\Lib\site-packages\django\core\handlers\exception.py", line 55, in inner
    response = get_response(request)
               ^^^^^^^^^^^^^^^^^^^^^
  File "C:\Users\caval\AppData\Local\Programs\Python\Python312\Lib\site-packages\django\core\handlers\base.py", line 197, in _get_response
    response = wrapped_callback(request, *callback_args, **callback_kwargs)
               ^^^^^^^^^^^^^^^^^^^^^^^^^^^^^^^^^^^^^^^^^^^^^^^^^^^^^^^^^^^^
  File "C:\Users\caval\AppData\Local\Programs\Python\Python312\Lib\site-packages\django\contrib\auth\decorators.py", line 59, in _view_wrapper
    return view_func(request, *args, **kwargs)
           ^^^^^^^^^^^^^^^^^^^^^^^^^^^^^^^^^^^
  File "C:\Users\caval\OneDrive\Desktop\projeto-portal-v2\apps\participacao\decorators.py", line 15, in wrapper
    funcionario = request.user.funcionario
                  ^^^^^^^^^^^^^^^^^^^^^^^^
  File "C:\Users\caval\AppData\Local\Programs\Python\Python312\Lib\site-packages\django\utils\functional.py", line 253, in inner
    return func(_wrapped, *args)
           ^^^^^^^^^^^^^^^^^^^^^
  File "C:\Users\caval\AppData\Local\Programs\Python\Python312\Lib\site-packages\django\db\models\fields\related_descriptors.py", line 520, in __get__
    rel_obj = self.get_queryset(instance=instance).get(**filter_args)
              ^^^^^^^^^^^^^^^^^^^^^^^^^^^^^^^^^^^^^^^^^^^^^^^^^^^^^^^
  File "C:\Users\caval\AppData\Local\Programs\Python\Python312\Lib\site-packages\django\db\models\query.py", line 629, in get
    num = len(clone)
          ^^^^^^^^^^
  File "C:\Users\caval\AppData\Local\Programs\Python\Python312\Lib\site-packages\django\db\models\query.py", line 366, in __len__
    self._fetch_all()
  File "C:\Users\caval\AppData\Local\Programs\Python\Python312\Lib\site-packages\django\db\models\query.py", line 1935, in _fetch_all
    self._result_cache = list(self._iterable_class(self))
                         ^^^^^^^^^^^^^^^^^^^^^^^^^^^^^^^^
  File "C:\Users\caval\AppData\Local\Programs\Python\Python312\Lib\site-packages\django\db\models\query.py", line 91, in __iter__
    results = compiler.execute_sql(
              ^^^^^^^^^^^^^^^^^^^^^
  File "C:\Users\caval\AppData\Local\Programs\Python\Python312\Lib\site-packages\django\db\models\sql\compiler.py", line 1622, in execute_sql
    cursor.execute(sql, params)
  File "C:\Users\caval\AppData\Local\Programs\Python\Python312\Lib\site-packages\django\db\backends\utils.py", line 122, in execute
    return super().execute(sql, params)
           ^^^^^^^^^^^^^^^^^^^^^^^^^^^^
  File "C:\Users\caval\AppData\Local\Programs\Python\Python312\Lib\site-packages\django\db\backends\utils.py", line 79, in execute
    return self._execute_with_wrappers(
           ^^^^^^^^^^^^^^^^^^^^^^^^^^^^
  File "C:\Users\caval\AppData\Local\Programs\Python\Python312\Lib\site-packages\django\db\backends\utils.py", line 92, in _execute_with_wrappers
    return executor(sql, params, many, context)
           ^^^^^^^^^^^^^^^^^^^^^^^^^^^^^^^^^^^^
  File "C:\Users\caval\AppData\Local\Programs\Python\Python312\Lib\site-packages\django\db\backends\utils.py", line 100, in _execute
    with self.db.wrap_database_errors:
         ^^^^^^^^^^^^^^^^^^^^^^^^^^^^
  File "C:\Users\caval\AppData\Local\Programs\Python\Python312\Lib\site-packages\django\db\utils.py", line 91, in __exit__
    raise dj_exc_value.with_traceback(traceback) from exc_value
  File "C:\Users\caval\AppData\Local\Programs\Python\Python312\Lib\site-packages\django\db\backends\utils.py", line 105, in _execute
    return self.cursor.execute(sql, params)
           ^^^^^^^^^^^^^^^^^^^^^^^^^^^^^^^^
django.db.utils.ProgrammingError: ERRO:  relação "participacao_funcionario" não existe
LINE 1: ...or", "participacao_funcionario"."abono_type" FROM "participa...
                                                             ^

2025-06-11 22:33:38,548 [ERROR] Erro ao registrar tentativa de login: name 'User' is not defined
2025-06-11 22:33:40,656 [INFO] Usuário admin acessando página inicial
2025-06-11 22:33:40,725 [ERROR] Internal Server Error: /participacao/
Traceback (most recent call last):
  File "C:\Users\caval\AppData\Local\Programs\Python\Python312\Lib\site-packages\django\core\handlers\exception.py", line 55, in inner
    response = get_response(request)
               ^^^^^^^^^^^^^^^^^^^^^
  File "C:\Users\caval\AppData\Local\Programs\Python\Python312\Lib\site-packages\django\core\handlers\base.py", line 197, in _get_response
    response = wrapped_callback(request, *callback_args, **callback_kwargs)
               ^^^^^^^^^^^^^^^^^^^^^^^^^^^^^^^^^^^^^^^^^^^^^^^^^^^^^^^^^^^^
  File "C:\Users\caval\AppData\Local\Programs\Python\Python312\Lib\site-packages\django\contrib\auth\decorators.py", line 59, in _view_wrapper
    return view_func(request, *args, **kwargs)
           ^^^^^^^^^^^^^^^^^^^^^^^^^^^^^^^^^^^
  File "C:\Users\caval\OneDrive\Desktop\projeto-portal-v2\apps\participacao\views\participation.py", line 80, in index
    setores = Setor.objects.annotate(total_funcionarios=Count('funcionarios')).order_by('nome')
              ^^^^^^^^^^^^^^^^^^^^^^^^^^^^^^^^^^^^^^^^^^^^^^^^^^^^^^^^^^^^^^^^
  File "C:\Users\caval\AppData\Local\Programs\Python\Python312\Lib\site-packages\django\db\models\manager.py", line 87, in manager_method
    return getattr(self.get_queryset(), name)(*args, **kwargs)
           ^^^^^^^^^^^^^^^^^^^^^^^^^^^^^^^^^^^^^^^^^^^^^^^^^^^
  File "C:\Users\caval\AppData\Local\Programs\Python\Python312\Lib\site-packages\django\db\models\query.py", line 1635, in annotate
    return self._annotate(args, kwargs, select=True)
           ^^^^^^^^^^^^^^^^^^^^^^^^^^^^^^^^^^^^^^^^^
  File "C:\Users\caval\AppData\Local\Programs\Python\Python312\Lib\site-packages\django\db\models\query.py", line 1687, in _annotate
    clone.query.add_annotation(
  File "C:\Users\caval\AppData\Local\Programs\Python\Python312\Lib\site-packages\django\db\models\sql\query.py", line 1218, in add_annotation
    annotation = annotation.resolve_expression(self, allow_joins=True, reuse=None)
                 ^^^^^^^^^^^^^^^^^^^^^^^^^^^^^^^^^^^^^^^^^^^^^^^^^^^^^^^^^^^^^^^^^
  File "C:\Users\caval\AppData\Local\Programs\Python\Python312\Lib\site-packages\django\db\models\aggregates.py", line 181, in resolve_expression
    result = super().resolve_expression(*args, **kwargs)
             ^^^^^^^^^^^^^^^^^^^^^^^^^^^^^^^^^^^^^^^^^^^
  File "C:\Users\caval\AppData\Local\Programs\Python\Python312\Lib\site-packages\django\db\models\aggregates.py", line 63, in resolve_expression
    c = super().resolve_expression(query, allow_joins, reuse, summarize)
        ^^^^^^^^^^^^^^^^^^^^^^^^^^^^^^^^^^^^^^^^^^^^^^^^^^^^^^^^^^^^^^^^
  File "C:\Users\caval\AppData\Local\Programs\Python\Python312\Lib\site-packages\django\db\models\expressions.py", line 300, in resolve_expression
    expr.resolve_expression(query, allow_joins, reuse, summarize)
  File "C:\Users\caval\AppData\Local\Programs\Python\Python312\Lib\site-packages\django\db\models\expressions.py", line 902, in resolve_expression
    return query.resolve_ref(self.name, allow_joins, reuse, summarize)
           ^^^^^^^^^^^^^^^^^^^^^^^^^^^^^^^^^^^^^^^^^^^^^^^^^^^^^^^^^^^
  File "C:\Users\caval\AppData\Local\Programs\Python\Python312\Lib\site-packages\django\db\models\sql\query.py", line 2046, in resolve_ref
    join_info = self.setup_joins(
                ^^^^^^^^^^^^^^^^^
  File "C:\Users\caval\AppData\Local\Programs\Python\Python312\Lib\site-packages\django\db\models\sql\query.py", line 1897, in setup_joins
    path, final_field, targets, rest = self.names_to_path(
                                       ^^^^^^^^^^^^^^^^^^^
  File "C:\Users\caval\AppData\Local\Programs\Python\Python312\Lib\site-packages\django\db\models\sql\query.py", line 1802, in names_to_path
    raise FieldError(
django.core.exceptions.FieldError: Cannot resolve keyword 'funcionarios' into field. Choices are: aprovacaosetor, ativo, funcionario, id, nome, recebe_participacao, valor_base
2025-06-11 22:33:58,299 [WARNING] Not Found: /favicon.ico
2025-06-11 22:54:46,210 [INFO] C:\Users\caval\OneDrive\Desktop\projeto-portal-v2\apps\participacao\admin.py changed, reloading.
2025-06-11 22:54:58,073 [WARNING] Not Found: /favicon.ico
2025-06-11 22:55:02,458 [ERROR] Erro ao registrar tentativa de login: name 'User' is not defined
2025-06-11 22:55:04,889 [INFO] Usuário admin acessando página inicial
2025-06-11 22:55:04,980 [ERROR] Internal Server Error: /participacao/
Traceback (most recent call last):
  File "C:\Users\caval\AppData\Local\Programs\Python\Python312\Lib\site-packages\django\core\handlers\exception.py", line 55, in inner
    response = get_response(request)
               ^^^^^^^^^^^^^^^^^^^^^
  File "C:\Users\caval\AppData\Local\Programs\Python\Python312\Lib\site-packages\django\core\handlers\base.py", line 197, in _get_response
    response = wrapped_callback(request, *callback_args, **callback_kwargs)
               ^^^^^^^^^^^^^^^^^^^^^^^^^^^^^^^^^^^^^^^^^^^^^^^^^^^^^^^^^^^^
  File "C:\Users\caval\AppData\Local\Programs\Python\Python312\Lib\site-packages\django\contrib\auth\decorators.py", line 59, in _view_wrapper
    return view_func(request, *args, **kwargs)
           ^^^^^^^^^^^^^^^^^^^^^^^^^^^^^^^^^^^
  File "C:\Users\caval\OneDrive\Desktop\projeto-portal-v2\apps\participacao\views\participation.py", line 80, in index
    setores = Setor.objects.annotate(total_funcionarios=Count('funcionarios')).order_by('nome')
              ^^^^^^^^^^^^^^^^^^^^^^^^^^^^^^^^^^^^^^^^^^^^^^^^^^^^^^^^^^^^^^^^
  File "C:\Users\caval\AppData\Local\Programs\Python\Python312\Lib\site-packages\django\db\models\manager.py", line 87, in manager_method
    return getattr(self.get_queryset(), name)(*args, **kwargs)
           ^^^^^^^^^^^^^^^^^^^^^^^^^^^^^^^^^^^^^^^^^^^^^^^^^^^
  File "C:\Users\caval\AppData\Local\Programs\Python\Python312\Lib\site-packages\django\db\models\query.py", line 1635, in annotate
    return self._annotate(args, kwargs, select=True)
           ^^^^^^^^^^^^^^^^^^^^^^^^^^^^^^^^^^^^^^^^^
  File "C:\Users\caval\AppData\Local\Programs\Python\Python312\Lib\site-packages\django\db\models\query.py", line 1687, in _annotate
    clone.query.add_annotation(
  File "C:\Users\caval\AppData\Local\Programs\Python\Python312\Lib\site-packages\django\db\models\sql\query.py", line 1218, in add_annotation
    annotation = annotation.resolve_expression(self, allow_joins=True, reuse=None)
                 ^^^^^^^^^^^^^^^^^^^^^^^^^^^^^^^^^^^^^^^^^^^^^^^^^^^^^^^^^^^^^^^^^
  File "C:\Users\caval\AppData\Local\Programs\Python\Python312\Lib\site-packages\django\db\models\aggregates.py", line 181, in resolve_expression
    result = super().resolve_expression(*args, **kwargs)
             ^^^^^^^^^^^^^^^^^^^^^^^^^^^^^^^^^^^^^^^^^^^
  File "C:\Users\caval\AppData\Local\Programs\Python\Python312\Lib\site-packages\django\db\models\aggregates.py", line 63, in resolve_expression
    c = super().resolve_expression(query, allow_joins, reuse, summarize)
        ^^^^^^^^^^^^^^^^^^^^^^^^^^^^^^^^^^^^^^^^^^^^^^^^^^^^^^^^^^^^^^^^
  File "C:\Users\caval\AppData\Local\Programs\Python\Python312\Lib\site-packages\django\db\models\expressions.py", line 300, in resolve_expression
    expr.resolve_expression(query, allow_joins, reuse, summarize)
  File "C:\Users\caval\AppData\Local\Programs\Python\Python312\Lib\site-packages\django\db\models\expressions.py", line 902, in resolve_expression
    return query.resolve_ref(self.name, allow_joins, reuse, summarize)
           ^^^^^^^^^^^^^^^^^^^^^^^^^^^^^^^^^^^^^^^^^^^^^^^^^^^^^^^^^^^
  File "C:\Users\caval\AppData\Local\Programs\Python\Python312\Lib\site-packages\django\db\models\sql\query.py", line 2046, in resolve_ref
    join_info = self.setup_joins(
                ^^^^^^^^^^^^^^^^^
  File "C:\Users\caval\AppData\Local\Programs\Python\Python312\Lib\site-packages\django\db\models\sql\query.py", line 1897, in setup_joins
    path, final_field, targets, rest = self.names_to_path(
                                       ^^^^^^^^^^^^^^^^^^^
  File "C:\Users\caval\AppData\Local\Programs\Python\Python312\Lib\site-packages\django\db\models\sql\query.py", line 1802, in names_to_path
    raise FieldError(
django.core.exceptions.FieldError: Cannot resolve keyword 'funcionarios' into field. Choices are: aprovacaosetor, ativo, funcionario, id, nome, recebe_participacao, valor_base
2025-06-11 22:57:02,351 [ERROR] Erro ao registrar tentativa de login: name 'User' is not defined
2025-06-11 22:57:03,598 [WARNING] Falha na tentativa de login: username=admin, IP=127.0.0.1
2025-06-11 22:57:09,028 [ERROR] Erro ao registrar tentativa de login: name 'User' is not defined
2025-06-11 22:57:10,269 [WARNING] Falha na tentativa de login: username=admin, IP=127.0.0.1
2025-06-11 22:57:55,357 [INFO] Usuário admin acessando página inicial
2025-06-11 22:57:55,448 [ERROR] Internal Server Error: /participacao/
Traceback (most recent call last):
  File "C:\Users\caval\AppData\Local\Programs\Python\Python312\Lib\site-packages\django\core\handlers\exception.py", line 55, in inner
    response = get_response(request)
               ^^^^^^^^^^^^^^^^^^^^^
  File "C:\Users\caval\AppData\Local\Programs\Python\Python312\Lib\site-packages\django\core\handlers\base.py", line 197, in _get_response
    response = wrapped_callback(request, *callback_args, **callback_kwargs)
               ^^^^^^^^^^^^^^^^^^^^^^^^^^^^^^^^^^^^^^^^^^^^^^^^^^^^^^^^^^^^
  File "C:\Users\caval\AppData\Local\Programs\Python\Python312\Lib\site-packages\django\contrib\auth\decorators.py", line 59, in _view_wrapper
    return view_func(request, *args, **kwargs)
           ^^^^^^^^^^^^^^^^^^^^^^^^^^^^^^^^^^^
  File "C:\Users\caval\OneDrive\Desktop\projeto-portal-v2\apps\participacao\views\participation.py", line 80, in index
    setores = Setor.objects.annotate(total_funcionarios=Count('funcionarios')).order_by('nome')
              ^^^^^^^^^^^^^^^^^^^^^^^^^^^^^^^^^^^^^^^^^^^^^^^^^^^^^^^^^^^^^^^^
  File "C:\Users\caval\AppData\Local\Programs\Python\Python312\Lib\site-packages\django\db\models\manager.py", line 87, in manager_method
    return getattr(self.get_queryset(), name)(*args, **kwargs)
           ^^^^^^^^^^^^^^^^^^^^^^^^^^^^^^^^^^^^^^^^^^^^^^^^^^^
  File "C:\Users\caval\AppData\Local\Programs\Python\Python312\Lib\site-packages\django\db\models\query.py", line 1635, in annotate
    return self._annotate(args, kwargs, select=True)
           ^^^^^^^^^^^^^^^^^^^^^^^^^^^^^^^^^^^^^^^^^
  File "C:\Users\caval\AppData\Local\Programs\Python\Python312\Lib\site-packages\django\db\models\query.py", line 1687, in _annotate
    clone.query.add_annotation(
  File "C:\Users\caval\AppData\Local\Programs\Python\Python312\Lib\site-packages\django\db\models\sql\query.py", line 1218, in add_annotation
    annotation = annotation.resolve_expression(self, allow_joins=True, reuse=None)
                 ^^^^^^^^^^^^^^^^^^^^^^^^^^^^^^^^^^^^^^^^^^^^^^^^^^^^^^^^^^^^^^^^^
  File "C:\Users\caval\AppData\Local\Programs\Python\Python312\Lib\site-packages\django\db\models\aggregates.py", line 181, in resolve_expression
    result = super().resolve_expression(*args, **kwargs)
             ^^^^^^^^^^^^^^^^^^^^^^^^^^^^^^^^^^^^^^^^^^^
  File "C:\Users\caval\AppData\Local\Programs\Python\Python312\Lib\site-packages\django\db\models\aggregates.py", line 63, in resolve_expression
    c = super().resolve_expression(query, allow_joins, reuse, summarize)
        ^^^^^^^^^^^^^^^^^^^^^^^^^^^^^^^^^^^^^^^^^^^^^^^^^^^^^^^^^^^^^^^^
  File "C:\Users\caval\AppData\Local\Programs\Python\Python312\Lib\site-packages\django\db\models\expressions.py", line 300, in resolve_expression
    expr.resolve_expression(query, allow_joins, reuse, summarize)
  File "C:\Users\caval\AppData\Local\Programs\Python\Python312\Lib\site-packages\django\db\models\expressions.py", line 902, in resolve_expression
    return query.resolve_ref(self.name, allow_joins, reuse, summarize)
           ^^^^^^^^^^^^^^^^^^^^^^^^^^^^^^^^^^^^^^^^^^^^^^^^^^^^^^^^^^^
  File "C:\Users\caval\AppData\Local\Programs\Python\Python312\Lib\site-packages\django\db\models\sql\query.py", line 2046, in resolve_ref
    join_info = self.setup_joins(
                ^^^^^^^^^^^^^^^^^
  File "C:\Users\caval\AppData\Local\Programs\Python\Python312\Lib\site-packages\django\db\models\sql\query.py", line 1897, in setup_joins
    path, final_field, targets, rest = self.names_to_path(
                                       ^^^^^^^^^^^^^^^^^^^
  File "C:\Users\caval\AppData\Local\Programs\Python\Python312\Lib\site-packages\django\db\models\sql\query.py", line 1802, in names_to_path
    raise FieldError(
django.core.exceptions.FieldError: Cannot resolve keyword 'funcionarios' into field. Choices are: aprovacaosetor, ativo, funcionario, id, nome, recebe_participacao, valor_base
2025-06-12 08:01:46,856 [INFO] C:\Users\adm1t\AppData\Local\Programs\Python\Python312\Lib\site-packages\reportlab\pdfbase\_fontdata_enc_symbol.py changed, reloading.
2025-06-12 08:01:53,230 [WARNING] Not Found: /favicon.ico
2025-06-12 08:01:57,192 [ERROR] Erro ao registrar tentativa de login: name 'User' is not defined
2025-06-12 08:01:57,762 [ERROR] Internal Server Error: /participacao/login/
Traceback (most recent call last):
  File "C:\Users\adm1t\AppData\Local\Programs\Python\Python312\Lib\site-packages\django\db\backends\utils.py", line 105, in _execute
    return self.cursor.execute(sql, params)
           ^^^^^^^^^^^^^^^^^^^^^^^^^^^^^^^^
psycopg2.errors.UndefinedTable: ERRO:  relação "auth_user" não existe
LINE 1: ...user"."is_active", "auth_user"."date_joined" FROM "auth_user...
                                                             ^


The above exception was the direct cause of the following exception:

Traceback (most recent call last):
  File "C:\Users\adm1t\AppData\Local\Programs\Python\Python312\Lib\site-packages\django\core\handlers\exception.py", line 55, in inner
    response = get_response(request)
               ^^^^^^^^^^^^^^^^^^^^^
  File "C:\Users\adm1t\AppData\Local\Programs\Python\Python312\Lib\site-packages\django\core\handlers\base.py", line 197, in _get_response
    response = wrapped_callback(request, *callback_args, **callback_kwargs)
               ^^^^^^^^^^^^^^^^^^^^^^^^^^^^^^^^^^^^^^^^^^^^^^^^^^^^^^^^^^^^
  File "C:\Users\adm1t\Desktop\Projeto_Portal\Projeto_Portal_v2_trabalho\Migracao_Portal_v2\apps\participacao\views\auth.py", line 73, in login
    user = authenticate(request, username=username, password=password)
           ^^^^^^^^^^^^^^^^^^^^^^^^^^^^^^^^^^^^^^^^^^^^^^^^^^^^^^^^^^^
  File "C:\Users\adm1t\AppData\Local\Programs\Python\Python312\Lib\site-packages\django\views\decorators\debug.py", line 75, in sensitive_variables_wrapper
    return func(*func_args, **func_kwargs)
           ^^^^^^^^^^^^^^^^^^^^^^^^^^^^^^^
  File "C:\Users\adm1t\AppData\Local\Programs\Python\Python312\Lib\site-packages\django\contrib\auth\__init__.py", line 114, in authenticate
    user = backend.authenticate(request, **credentials)
           ^^^^^^^^^^^^^^^^^^^^^^^^^^^^^^^^^^^^^^^^^^^^
  File "C:\Users\adm1t\AppData\Local\Programs\Python\Python312\Lib\site-packages\django\contrib\auth\backends.py", line 65, in authenticate
    user = UserModel._default_manager.get_by_natural_key(username)
           ^^^^^^^^^^^^^^^^^^^^^^^^^^^^^^^^^^^^^^^^^^^^^^^^^^^^^^^
  File "C:\Users\adm1t\AppData\Local\Programs\Python\Python312\Lib\site-packages\django\contrib\auth\base_user.py", line 37, in get_by_natural_key
    return self.get(**{self.model.USERNAME_FIELD: username})
           ^^^^^^^^^^^^^^^^^^^^^^^^^^^^^^^^^^^^^^^^^^^^^^^^^
  File "C:\Users\adm1t\AppData\Local\Programs\Python\Python312\Lib\site-packages\django\db\models\manager.py", line 87, in manager_method
    return getattr(self.get_queryset(), name)(*args, **kwargs)
           ^^^^^^^^^^^^^^^^^^^^^^^^^^^^^^^^^^^^^^^^^^^^^^^^^^^
  File "C:\Users\adm1t\AppData\Local\Programs\Python\Python312\Lib\site-packages\django\db\models\query.py", line 629, in get
    num = len(clone)
          ^^^^^^^^^^
  File "C:\Users\adm1t\AppData\Local\Programs\Python\Python312\Lib\site-packages\django\db\models\query.py", line 366, in __len__
    self._fetch_all()
  File "C:\Users\adm1t\AppData\Local\Programs\Python\Python312\Lib\site-packages\django\db\models\query.py", line 1935, in _fetch_all
    self._result_cache = list(self._iterable_class(self))
                         ^^^^^^^^^^^^^^^^^^^^^^^^^^^^^^^^
  File "C:\Users\adm1t\AppData\Local\Programs\Python\Python312\Lib\site-packages\django\db\models\query.py", line 91, in __iter__
    results = compiler.execute_sql(
              ^^^^^^^^^^^^^^^^^^^^^
  File "C:\Users\adm1t\AppData\Local\Programs\Python\Python312\Lib\site-packages\django\db\models\sql\compiler.py", line 1622, in execute_sql
    cursor.execute(sql, params)
  File "C:\Users\adm1t\AppData\Local\Programs\Python\Python312\Lib\site-packages\django\db\backends\utils.py", line 122, in execute
    return super().execute(sql, params)
           ^^^^^^^^^^^^^^^^^^^^^^^^^^^^
  File "C:\Users\adm1t\AppData\Local\Programs\Python\Python312\Lib\site-packages\django\db\backends\utils.py", line 79, in execute
    return self._execute_with_wrappers(
           ^^^^^^^^^^^^^^^^^^^^^^^^^^^^
  File "C:\Users\adm1t\AppData\Local\Programs\Python\Python312\Lib\site-packages\django\db\backends\utils.py", line 92, in _execute_with_wrappers
    return executor(sql, params, many, context)
           ^^^^^^^^^^^^^^^^^^^^^^^^^^^^^^^^^^^^
  File "C:\Users\adm1t\AppData\Local\Programs\Python\Python312\Lib\site-packages\django\db\backends\utils.py", line 100, in _execute
    with self.db.wrap_database_errors:
  File "C:\Users\adm1t\AppData\Local\Programs\Python\Python312\Lib\site-packages\django\db\utils.py", line 91, in __exit__
    raise dj_exc_value.with_traceback(traceback) from exc_value
  File "C:\Users\adm1t\AppData\Local\Programs\Python\Python312\Lib\site-packages\django\db\backends\utils.py", line 105, in _execute
    return self.cursor.execute(sql, params)
           ^^^^^^^^^^^^^^^^^^^^^^^^^^^^^^^^
django.db.utils.ProgrammingError: ERRO:  relação "auth_user" não existe
LINE 1: ...user"."is_active", "auth_user"."date_joined" FROM "auth_user...
                                                             ^

2025-06-12 08:02:15,875 [INFO] C:\Users\adm1t\AppData\Local\Programs\Python\Python312\Lib\site-packages\psycopg2\_json.py changed, reloading.
2025-06-12 08:06:31,514 [INFO] C:\Users\adm1t\Desktop\Projeto_Portal\Projeto_Portal_v2_trabalho\Migracao_Portal_v2\apps\participacao\apps.py changed, reloading.
2025-06-12 08:16:20,747 [WARNING] Not Found: /login/
2025-06-12 08:16:25,397 [WARNING] Not Found: /login
2025-06-12 08:18:54,369 [INFO] C:\Users\adm1t\Desktop\Projeto_Portal\Projeto_Portal_v2_trabalho\Migracao_Portal_v2\apps\participacao\models\funcionario.py changed, reloading.
2025-06-12 08:19:59,776 [ERROR] Erro ao registrar tentativa de login: name 'User' is not defined
2025-06-12 08:20:00,618 [WARNING] Falha na tentativa de login: username=admin, IP=127.0.0.1
2025-06-12 08:20:07,079 [ERROR] Erro ao registrar tentativa de login: name 'User' is not defined
2025-06-12 08:20:08,083 [WARNING] Falha na tentativa de login: username=admin, IP=127.0.0.1
2025-06-12 08:21:11,314 [ERROR] Erro ao registrar tentativa de login: name 'User' is not defined
2025-06-12 08:21:12,297 [WARNING] Falha na tentativa de login: username=admin, IP=127.0.0.1
2025-06-12 08:42:19,954 [INFO] C:\Users\adm1t\Desktop\Projeto_Portal\Projeto_Portal_v2_trabalho\Migracao_Portal_v2\apps\participacao\models\funcionario.py changed, reloading.
2025-06-12 08:44:14,771 [INFO] C:\Users\adm1t\Desktop\Projeto_Portal\Projeto_Portal_v2_trabalho\Migracao_Portal_v2\apps\participacao\views\auth.py changed, reloading.
2025-06-12 08:47:19,277 [INFO] Registrada tentativa de login: username=admin, IP=127.0.0.1, Maliciosa=False
2025-06-12 08:47:19,982 [WARNING] Falha na tentativa de login: username=admin, IP=127.0.0.1
2025-06-12 09:19:55,656 [INFO] Registrada tentativa de login: username=admin, IP=127.0.0.1, Maliciosa=False
2025-06-12 09:19:56,351 [INFO] Usuário admin acessando página inicial
2025-06-12 09:19:56,356 [INFO] Dados setores: {'labels': [], 'data': []}
2025-06-12 09:19:56,357 [ERROR] Usuário admin sem Funcionario associado
2025-06-12 09:20:07,590 [DEBUG] Processando requisição para /participacao/participacao/ - Usuário autenticado: True
2025-06-12 09:20:07,592 [ERROR] Usuário admin não tem Funcionario associado.
2025-06-12 09:34:07,178 [INFO] Registrada tentativa de login: username=admin, IP=127.0.0.1, Maliciosa=False
2025-06-12 09:34:07,884 [INFO] Usuário admin acessando página inicial
2025-06-12 09:34:07,889 [INFO] Dados setores: {'labels': [], 'data': []}
2025-06-12 09:34:07,890 [ERROR] Usuário admin sem Funcionario associado
2025-06-12 09:34:16,260 [DEBUG] Processando requisição para /participacao/configurar_participacao_setor/ - Usuário autenticado: True
2025-06-12 09:34:16,262 [ERROR] Usuário admin não tem Funcionario associado.
2025-06-12 09:34:22,385 [INFO] Registrada tentativa de login: username=admin, IP=127.0.0.1, Maliciosa=False
2025-06-12 09:34:23,100 [INFO] Usuário admin acessando página inicial
2025-06-12 09:34:23,103 [INFO] Dados setores: {'labels': [], 'data': []}
2025-06-12 09:34:23,105 [ERROR] Usuário admin sem Funcionario associado
2025-06-12 09:34:28,331 [DEBUG] Processando requisição para /participacao/participacao/ - Usuário autenticado: True
2025-06-12 09:34:28,333 [ERROR] Usuário admin não tem Funcionario associado.
2025-06-12 09:38:48,736 [INFO] Registrada tentativa de login: username=admin, IP=127.0.0.1, Maliciosa=False
2025-06-12 09:38:49,577 [INFO] Usuário admin acessando página inicial
2025-06-12 09:38:49,580 [INFO] Dados setores: {'labels': [], 'data': []}
2025-06-12 09:38:49,582 [ERROR] Usuário admin sem Funcionario associado
2025-06-12 09:38:52,466 [DEBUG] Processando requisição para /participacao/funcionarios/ - Usuário autenticado: True
2025-06-12 09:38:52,468 [ERROR] Usuário admin não tem Funcionario associado.
2025-06-12 09:39:23,179 [INFO] C:\Users\adm1t\Desktop\Projeto_Portal\Projeto_Portal_v2_trabalho\Migracao_Portal_v2\apps\participacao\views\participation.py changed, reloading.
2025-06-12 09:39:26,908 [INFO] Registrada tentativa de login: username=admin, IP=127.0.0.1, Maliciosa=False
2025-06-12 09:39:27,939 [INFO] Usuário admin acessando página inicial
2025-06-12 09:39:27,944 [INFO] Dados setores: {'labels': [], 'data': []}
2025-06-12 09:39:27,947 [ERROR] Usuário admin sem Funcionario associado
2025-06-12 09:39:30,381 [INFO] Usuário admin acessando lista de funcionários
2025-06-12 09:39:30,384 [INFO] Total funcionários: 0
2025-06-12 09:39:30,533 [ERROR] Internal Server Error: /participacao/funcionarios/
Traceback (most recent call last):
  File "C:\Users\adm1t\AppData\Local\Programs\Python\Python312\Lib\site-packages\django\template\defaulttags.py", line 1035, in find_library
    return parser.libraries[name]
           ~~~~~~~~~~~~~~~~^^^^^^
KeyError: 'filters'

During handling of the above exception, another exception occurred:

Traceback (most recent call last):
  File "C:\Users\adm1t\AppData\Local\Programs\Python\Python312\Lib\site-packages\django\core\handlers\exception.py", line 55, in inner
    response = get_response(request)
               ^^^^^^^^^^^^^^^^^^^^^
  File "C:\Users\adm1t\AppData\Local\Programs\Python\Python312\Lib\site-packages\django\core\handlers\base.py", line 197, in _get_response
    response = wrapped_callback(request, *callback_args, **callback_kwargs)
               ^^^^^^^^^^^^^^^^^^^^^^^^^^^^^^^^^^^^^^^^^^^^^^^^^^^^^^^^^^^^
  File "C:\Users\adm1t\AppData\Local\Programs\Python\Python312\Lib\site-packages\django\contrib\auth\decorators.py", line 59, in _view_wrapper
    return view_func(request, *args, **kwargs)
           ^^^^^^^^^^^^^^^^^^^^^^^^^^^^^^^^^^^
  File "C:\Users\adm1t\AppData\Local\Programs\Python\Python312\Lib\contextlib.py", line 81, in inner
    return func(*args, **kwds)
           ^^^^^^^^^^^^^^^^^^^
  File "C:\Users\adm1t\Desktop\Projeto_Portal\Projeto_Portal_v2_trabalho\Migracao_Portal_v2\apps\participacao\views\participation.py", line 944, in funcionarios
    return render(request, 'participacao/funcionarios.html', {
           ^^^^^^^^^^^^^^^^^^^^^^^^^^^^^^^^^^^^^^^^^^^^^^^^^^^
  File "C:\Users\adm1t\AppData\Local\Programs\Python\Python312\Lib\site-packages\django\shortcuts.py", line 25, in render
    content = loader.render_to_string(template_name, context, request, using=using)
              ^^^^^^^^^^^^^^^^^^^^^^^^^^^^^^^^^^^^^^^^^^^^^^^^^^^^^^^^^^^^^^^^^^^^^
  File "C:\Users\adm1t\AppData\Local\Programs\Python\Python312\Lib\site-packages\django\template\loader.py", line 61, in render_to_string
    template = get_template(template_name, using=using)
               ^^^^^^^^^^^^^^^^^^^^^^^^^^^^^^^^^^^^^^^^
  File "C:\Users\adm1t\AppData\Local\Programs\Python\Python312\Lib\site-packages\django\template\loader.py", line 15, in get_template
    return engine.get_template(template_name)
           ^^^^^^^^^^^^^^^^^^^^^^^^^^^^^^^^^^
  File "C:\Users\adm1t\AppData\Local\Programs\Python\Python312\Lib\site-packages\django\template\backends\django.py", line 79, in get_template
    return Template(self.engine.get_template(template_name), self)
                    ^^^^^^^^^^^^^^^^^^^^^^^^^^^^^^^^^^^^^^^
  File "C:\Users\adm1t\AppData\Local\Programs\Python\Python312\Lib\site-packages\django\template\engine.py", line 177, in get_template
    template, origin = self.find_template(template_name)
                       ^^^^^^^^^^^^^^^^^^^^^^^^^^^^^^^^^
  File "C:\Users\adm1t\AppData\Local\Programs\Python\Python312\Lib\site-packages\django\template\engine.py", line 159, in find_template
    template = loader.get_template(name, skip=skip)
               ^^^^^^^^^^^^^^^^^^^^^^^^^^^^^^^^^^^^
  File "C:\Users\adm1t\AppData\Local\Programs\Python\Python312\Lib\site-packages\django\template\loaders\cached.py", line 57, in get_template
    template = super().get_template(template_name, skip)
               ^^^^^^^^^^^^^^^^^^^^^^^^^^^^^^^^^^^^^^^^^
  File "C:\Users\adm1t\AppData\Local\Programs\Python\Python312\Lib\site-packages\django\template\loaders\base.py", line 28, in get_template
    return Template(
           ^^^^^^^^^
  File "C:\Users\adm1t\AppData\Local\Programs\Python\Python312\Lib\site-packages\django\template\base.py", line 154, in __init__
    self.nodelist = self.compile_nodelist()
                    ^^^^^^^^^^^^^^^^^^^^^^^
  File "C:\Users\adm1t\AppData\Local\Programs\Python\Python312\Lib\site-packages\django\template\base.py", line 196, in compile_nodelist
    nodelist = parser.parse()
               ^^^^^^^^^^^^^^
  File "C:\Users\adm1t\AppData\Local\Programs\Python\Python312\Lib\site-packages\django\template\base.py", line 518, in parse
    raise self.error(token, e)
  File "C:\Users\adm1t\AppData\Local\Programs\Python\Python312\Lib\site-packages\django\template\base.py", line 516, in parse
    compiled_result = compile_func(self, token)
                      ^^^^^^^^^^^^^^^^^^^^^^^^^
  File "C:\Users\adm1t\AppData\Local\Programs\Python\Python312\Lib\site-packages\django\template\defaulttags.py", line 1097, in load
    lib = find_library(parser, name)
          ^^^^^^^^^^^^^^^^^^^^^^^^^^
  File "C:\Users\adm1t\AppData\Local\Programs\Python\Python312\Lib\site-packages\django\template\defaulttags.py", line 1037, in find_library
    raise TemplateSyntaxError(
django.template.exceptions.TemplateSyntaxError: 'filters' is not a registered tag library. Must be one of:
admin_list
admin_modify
admin_urls
cache
i18n
l10n
log
static
tz
2025-06-12 09:39:50,152 [DEBUG] Processando requisição para /participacao/participacao/ - Usuário autenticado: True
2025-06-12 09:39:50,155 [ERROR] Usuário admin não tem Funcionario associado.
2025-06-12 09:42:53,849 [INFO] Registrada tentativa de login: username=admin, IP=127.0.0.1, Maliciosa=True
2025-06-12 09:42:54,667 [INFO] Usuário admin acessando página inicial
2025-06-12 09:42:54,671 [INFO] Dados setores: {'labels': ['Admin'], 'data': [1]}
2025-06-12 09:42:54,673 [DEBUG] Usuário admin - Tipo: master_admin, Pode ver: True
2025-06-12 09:42:58,093 [DEBUG] Processando requisição para /participacao/participacao/ - Usuário autenticado: True
2025-06-12 09:42:58,095 [INFO] Usuário admin acessando participação
2025-06-12 09:42:58,095 [DEBUG] Último trimestre: 2025-Q2
2025-06-12 09:42:58,123 [ERROR] Internal Server Error: /participacao/participacao/
Traceback (most recent call last):
  File "C:\Users\adm1t\AppData\Local\Programs\Python\Python312\Lib\site-packages\django\core\handlers\exception.py", line 55, in inner
    response = get_response(request)
               ^^^^^^^^^^^^^^^^^^^^^
  File "C:\Users\adm1t\AppData\Local\Programs\Python\Python312\Lib\site-packages\django\core\handlers\base.py", line 197, in _get_response
    response = wrapped_callback(request, *callback_args, **callback_kwargs)
               ^^^^^^^^^^^^^^^^^^^^^^^^^^^^^^^^^^^^^^^^^^^^^^^^^^^^^^^^^^^^
  File "C:\Users\adm1t\AppData\Local\Programs\Python\Python312\Lib\site-packages\django\contrib\auth\decorators.py", line 59, in _view_wrapper
    return view_func(request, *args, **kwargs)
           ^^^^^^^^^^^^^^^^^^^^^^^^^^^^^^^^^^^
  File "C:\Users\adm1t\Desktop\Projeto_Portal\Projeto_Portal_v2_trabalho\Migracao_Portal_v2\apps\participacao\decorators.py", line 21, in wrapper
    return view_func(request, *args, **kwargs)
           ^^^^^^^^^^^^^^^^^^^^^^^^^^^^^^^^^^^
  File "C:\Users\adm1t\Desktop\Projeto_Portal\Projeto_Portal_v2_trabalho\Migracao_Portal_v2\apps\participacao\views\participation.py", line 864, in participacao
    Q(data_admissao__isnull=True) | Q(usuario__isnull=True)
    ^
NameError: name 'Q' is not defined
2025-06-12 09:44:05,331 [DEBUG] Processando requisição para /participacao/configurar_participacao_setor/ - Usuário autenticado: True
2025-06-12 09:44:05,334 [INFO] Usuário admin acessando configuração de participação por setor
2025-06-12 09:44:05,392 [ERROR] Internal Server Error: /participacao/configurar_participacao_setor/
Traceback (most recent call last):
  File "C:\Users\adm1t\AppData\Local\Programs\Python\Python312\Lib\site-packages\django\template\defaulttags.py", line 1035, in find_library
    return parser.libraries[name]
           ~~~~~~~~~~~~~~~~^^^^^^
KeyError: 'filters'

During handling of the above exception, another exception occurred:

Traceback (most recent call last):
  File "C:\Users\adm1t\AppData\Local\Programs\Python\Python312\Lib\site-packages\django\core\handlers\exception.py", line 55, in inner
    response = get_response(request)
               ^^^^^^^^^^^^^^^^^^^^^
  File "C:\Users\adm1t\AppData\Local\Programs\Python\Python312\Lib\site-packages\django\core\handlers\base.py", line 197, in _get_response
    response = wrapped_callback(request, *callback_args, **callback_kwargs)
               ^^^^^^^^^^^^^^^^^^^^^^^^^^^^^^^^^^^^^^^^^^^^^^^^^^^^^^^^^^^^
  File "C:\Users\adm1t\AppData\Local\Programs\Python\Python312\Lib\site-packages\django\contrib\auth\decorators.py", line 59, in _view_wrapper
    return view_func(request, *args, **kwargs)
           ^^^^^^^^^^^^^^^^^^^^^^^^^^^^^^^^^^^
  File "C:\Users\adm1t\Desktop\Projeto_Portal\Projeto_Portal_v2_trabalho\Migracao_Portal_v2\apps\participacao\decorators.py", line 21, in wrapper
    return view_func(request, *args, **kwargs)
           ^^^^^^^^^^^^^^^^^^^^^^^^^^^^^^^^^^^
  File "C:\Users\adm1t\Desktop\Projeto_Portal\Projeto_Portal_v2_trabalho\Migracao_Portal_v2\apps\participacao\views\participation.py", line 233, in configurar_participacao_setor
    return render(request, 'participacao/configurar_participacao_setor.html', {
           ^^^^^^^^^^^^^^^^^^^^^^^^^^^^^^^^^^^^^^^^^^^^^^^^^^^^^^^^^^^^^^^^^^^^
  File "C:\Users\adm1t\AppData\Local\Programs\Python\Python312\Lib\site-packages\django\shortcuts.py", line 25, in render
    content = loader.render_to_string(template_name, context, request, using=using)
              ^^^^^^^^^^^^^^^^^^^^^^^^^^^^^^^^^^^^^^^^^^^^^^^^^^^^^^^^^^^^^^^^^^^^^
  File "C:\Users\adm1t\AppData\Local\Programs\Python\Python312\Lib\site-packages\django\template\loader.py", line 61, in render_to_string
    template = get_template(template_name, using=using)
               ^^^^^^^^^^^^^^^^^^^^^^^^^^^^^^^^^^^^^^^^
  File "C:\Users\adm1t\AppData\Local\Programs\Python\Python312\Lib\site-packages\django\template\loader.py", line 15, in get_template
    return engine.get_template(template_name)
           ^^^^^^^^^^^^^^^^^^^^^^^^^^^^^^^^^^
  File "C:\Users\adm1t\AppData\Local\Programs\Python\Python312\Lib\site-packages\django\template\backends\django.py", line 79, in get_template
    return Template(self.engine.get_template(template_name), self)
                    ^^^^^^^^^^^^^^^^^^^^^^^^^^^^^^^^^^^^^^^
  File "C:\Users\adm1t\AppData\Local\Programs\Python\Python312\Lib\site-packages\django\template\engine.py", line 177, in get_template
    template, origin = self.find_template(template_name)
                       ^^^^^^^^^^^^^^^^^^^^^^^^^^^^^^^^^
  File "C:\Users\adm1t\AppData\Local\Programs\Python\Python312\Lib\site-packages\django\template\engine.py", line 159, in find_template
    template = loader.get_template(name, skip=skip)
               ^^^^^^^^^^^^^^^^^^^^^^^^^^^^^^^^^^^^
  File "C:\Users\adm1t\AppData\Local\Programs\Python\Python312\Lib\site-packages\django\template\loaders\cached.py", line 57, in get_template
    template = super().get_template(template_name, skip)
               ^^^^^^^^^^^^^^^^^^^^^^^^^^^^^^^^^^^^^^^^^
  File "C:\Users\adm1t\AppData\Local\Programs\Python\Python312\Lib\site-packages\django\template\loaders\base.py", line 28, in get_template
    return Template(
           ^^^^^^^^^
  File "C:\Users\adm1t\AppData\Local\Programs\Python\Python312\Lib\site-packages\django\template\base.py", line 154, in __init__
    self.nodelist = self.compile_nodelist()
                    ^^^^^^^^^^^^^^^^^^^^^^^
  File "C:\Users\adm1t\AppData\Local\Programs\Python\Python312\Lib\site-packages\django\template\base.py", line 196, in compile_nodelist
    nodelist = parser.parse()
               ^^^^^^^^^^^^^^
  File "C:\Users\adm1t\AppData\Local\Programs\Python\Python312\Lib\site-packages\django\template\base.py", line 518, in parse
    raise self.error(token, e)
  File "C:\Users\adm1t\AppData\Local\Programs\Python\Python312\Lib\site-packages\django\template\base.py", line 516, in parse
    compiled_result = compile_func(self, token)
                      ^^^^^^^^^^^^^^^^^^^^^^^^^
  File "C:\Users\adm1t\AppData\Local\Programs\Python\Python312\Lib\site-packages\django\template\defaulttags.py", line 1097, in load
    lib = find_library(parser, name)
          ^^^^^^^^^^^^^^^^^^^^^^^^^^
  File "C:\Users\adm1t\AppData\Local\Programs\Python\Python312\Lib\site-packages\django\template\defaulttags.py", line 1037, in find_library
    raise TemplateSyntaxError(
django.template.exceptions.TemplateSyntaxError: 'filters' is not a registered tag library. Must be one of:
admin_list
admin_modify
admin_urls
cache
i18n
l10n
log
static
tz
2025-06-12 09:44:05,516 [DEBUG] Processando requisição para /participacao/configurar_participacao_setor/ - Usuário autenticado: True
2025-06-12 09:44:05,518 [INFO] Usuário admin acessando configuração de participação por setor
2025-06-12 09:44:05,553 [ERROR] Internal Server Error: /participacao/configurar_participacao_setor/
Traceback (most recent call last):
  File "C:\Users\adm1t\AppData\Local\Programs\Python\Python312\Lib\site-packages\django\template\defaulttags.py", line 1035, in find_library
    return parser.libraries[name]
           ~~~~~~~~~~~~~~~~^^^^^^
KeyError: 'filters'

During handling of the above exception, another exception occurred:

Traceback (most recent call last):
  File "C:\Users\adm1t\AppData\Local\Programs\Python\Python312\Lib\site-packages\django\core\handlers\exception.py", line 55, in inner
    response = get_response(request)
               ^^^^^^^^^^^^^^^^^^^^^
  File "C:\Users\adm1t\AppData\Local\Programs\Python\Python312\Lib\site-packages\django\core\handlers\base.py", line 197, in _get_response
    response = wrapped_callback(request, *callback_args, **callback_kwargs)
               ^^^^^^^^^^^^^^^^^^^^^^^^^^^^^^^^^^^^^^^^^^^^^^^^^^^^^^^^^^^^
  File "C:\Users\adm1t\AppData\Local\Programs\Python\Python312\Lib\site-packages\django\contrib\auth\decorators.py", line 59, in _view_wrapper
    return view_func(request, *args, **kwargs)
           ^^^^^^^^^^^^^^^^^^^^^^^^^^^^^^^^^^^
  File "C:\Users\adm1t\Desktop\Projeto_Portal\Projeto_Portal_v2_trabalho\Migracao_Portal_v2\apps\participacao\decorators.py", line 21, in wrapper
    return view_func(request, *args, **kwargs)
           ^^^^^^^^^^^^^^^^^^^^^^^^^^^^^^^^^^^
  File "C:\Users\adm1t\Desktop\Projeto_Portal\Projeto_Portal_v2_trabalho\Migracao_Portal_v2\apps\participacao\views\participation.py", line 233, in configurar_participacao_setor
    return render(request, 'participacao/configurar_participacao_setor.html', {
           ^^^^^^^^^^^^^^^^^^^^^^^^^^^^^^^^^^^^^^^^^^^^^^^^^^^^^^^^^^^^^^^^^^^^
  File "C:\Users\adm1t\AppData\Local\Programs\Python\Python312\Lib\site-packages\django\shortcuts.py", line 25, in render
    content = loader.render_to_string(template_name, context, request, using=using)
              ^^^^^^^^^^^^^^^^^^^^^^^^^^^^^^^^^^^^^^^^^^^^^^^^^^^^^^^^^^^^^^^^^^^^^
  File "C:\Users\adm1t\AppData\Local\Programs\Python\Python312\Lib\site-packages\django\template\loader.py", line 61, in render_to_string
    template = get_template(template_name, using=using)
               ^^^^^^^^^^^^^^^^^^^^^^^^^^^^^^^^^^^^^^^^
  File "C:\Users\adm1t\AppData\Local\Programs\Python\Python312\Lib\site-packages\django\template\loader.py", line 15, in get_template
    return engine.get_template(template_name)
           ^^^^^^^^^^^^^^^^^^^^^^^^^^^^^^^^^^
  File "C:\Users\adm1t\AppData\Local\Programs\Python\Python312\Lib\site-packages\django\template\backends\django.py", line 79, in get_template
    return Template(self.engine.get_template(template_name), self)
                    ^^^^^^^^^^^^^^^^^^^^^^^^^^^^^^^^^^^^^^^
  File "C:\Users\adm1t\AppData\Local\Programs\Python\Python312\Lib\site-packages\django\template\engine.py", line 177, in get_template
    template, origin = self.find_template(template_name)
                       ^^^^^^^^^^^^^^^^^^^^^^^^^^^^^^^^^
  File "C:\Users\adm1t\AppData\Local\Programs\Python\Python312\Lib\site-packages\django\template\engine.py", line 159, in find_template
    template = loader.get_template(name, skip=skip)
               ^^^^^^^^^^^^^^^^^^^^^^^^^^^^^^^^^^^^
  File "C:\Users\adm1t\AppData\Local\Programs\Python\Python312\Lib\site-packages\django\template\loaders\cached.py", line 57, in get_template
    template = super().get_template(template_name, skip)
               ^^^^^^^^^^^^^^^^^^^^^^^^^^^^^^^^^^^^^^^^^
  File "C:\Users\adm1t\AppData\Local\Programs\Python\Python312\Lib\site-packages\django\template\loaders\base.py", line 28, in get_template
    return Template(
           ^^^^^^^^^
  File "C:\Users\adm1t\AppData\Local\Programs\Python\Python312\Lib\site-packages\django\template\base.py", line 154, in __init__
    self.nodelist = self.compile_nodelist()
                    ^^^^^^^^^^^^^^^^^^^^^^^
  File "C:\Users\adm1t\AppData\Local\Programs\Python\Python312\Lib\site-packages\django\template\base.py", line 196, in compile_nodelist
    nodelist = parser.parse()
               ^^^^^^^^^^^^^^
  File "C:\Users\adm1t\AppData\Local\Programs\Python\Python312\Lib\site-packages\django\template\base.py", line 518, in parse
    raise self.error(token, e)
  File "C:\Users\adm1t\AppData\Local\Programs\Python\Python312\Lib\site-packages\django\template\base.py", line 516, in parse
    compiled_result = compile_func(self, token)
                      ^^^^^^^^^^^^^^^^^^^^^^^^^
  File "C:\Users\adm1t\AppData\Local\Programs\Python\Python312\Lib\site-packages\django\template\defaulttags.py", line 1097, in load
    lib = find_library(parser, name)
          ^^^^^^^^^^^^^^^^^^^^^^^^^^
  File "C:\Users\adm1t\AppData\Local\Programs\Python\Python312\Lib\site-packages\django\template\defaulttags.py", line 1037, in find_library
    raise TemplateSyntaxError(
django.template.exceptions.TemplateSyntaxError: 'filters' is not a registered tag library. Must be one of:
admin_list
admin_modify
admin_urls
cache
i18n
l10n
log
static
tz
2025-06-12 09:44:07,303 [INFO] Usuário admin acessando página inicial
2025-06-12 09:44:07,308 [INFO] Dados setores: {'labels': ['Admin'], 'data': [1]}
2025-06-12 09:44:07,310 [DEBUG] Usuário admin - Tipo: master_admin, Pode ver: True
2025-06-12 09:44:08,472 [DEBUG] Processando requisição para /participacao/participacao/ - Usuário autenticado: True
2025-06-12 09:44:08,478 [INFO] Usuário admin acessando participação
2025-06-12 09:44:08,480 [DEBUG] Último trimestre: 2025-Q2
2025-06-12 09:44:08,523 [ERROR] Internal Server Error: /participacao/participacao/
Traceback (most recent call last):
  File "C:\Users\adm1t\AppData\Local\Programs\Python\Python312\Lib\site-packages\django\core\handlers\exception.py", line 55, in inner
    response = get_response(request)
               ^^^^^^^^^^^^^^^^^^^^^
  File "C:\Users\adm1t\AppData\Local\Programs\Python\Python312\Lib\site-packages\django\core\handlers\base.py", line 197, in _get_response
    response = wrapped_callback(request, *callback_args, **callback_kwargs)
               ^^^^^^^^^^^^^^^^^^^^^^^^^^^^^^^^^^^^^^^^^^^^^^^^^^^^^^^^^^^^
  File "C:\Users\adm1t\AppData\Local\Programs\Python\Python312\Lib\site-packages\django\contrib\auth\decorators.py", line 59, in _view_wrapper
    return view_func(request, *args, **kwargs)
           ^^^^^^^^^^^^^^^^^^^^^^^^^^^^^^^^^^^
  File "C:\Users\adm1t\Desktop\Projeto_Portal\Projeto_Portal_v2_trabalho\Migracao_Portal_v2\apps\participacao\decorators.py", line 21, in wrapper
    return view_func(request, *args, **kwargs)
           ^^^^^^^^^^^^^^^^^^^^^^^^^^^^^^^^^^^
  File "C:\Users\adm1t\Desktop\Projeto_Portal\Projeto_Portal_v2_trabalho\Migracao_Portal_v2\apps\participacao\views\participation.py", line 864, in participacao
    Q(data_admissao__isnull=True) | Q(usuario__isnull=True)
    ^
NameError: name 'Q' is not defined
2025-06-12 09:47:52,836 [INFO] C:\Users\adm1t\Desktop\Projeto_Portal\Projeto_Portal_v2_trabalho\Migracao_Portal_v2\apps\participacao\templates\participacao\templatetags\custom_filters.py changed, reloading.
2025-06-12 09:48:39,383 [INFO] C:\Users\adm1t\Desktop\Projeto_Portal\Projeto_Portal_v2_trabalho\Migracao_Portal_v2\apps\participacao\views\participation.py changed, reloading.
2025-06-12 09:49:34,499 [INFO] Registrada tentativa de login: username=admin, IP=127.0.0.1, Maliciosa=True
2025-06-12 09:49:35,234 [INFO] Usuário admin acessando página inicial
2025-06-12 09:49:35,240 [INFO] Dados setores: {'labels': ['Admin'], 'data': [1]}
2025-06-12 09:49:35,243 [DEBUG] Usuário admin - Tipo: master_admin, Pode ver: True
2025-06-12 09:49:36,887 [DEBUG] Processando requisição para /participacao/participacao/ - Usuário autenticado: True
2025-06-12 09:49:36,889 [INFO] Usuário admin acessando participação
2025-06-12 09:49:36,889 [DEBUG] Último trimestre: 2025-Q2
2025-06-12 09:49:36,964 [ERROR] Internal Server Error: /participacao/participacao/
Traceback (most recent call last):
  File "C:\Users\adm1t\AppData\Local\Programs\Python\Python312\Lib\site-packages\django\core\handlers\exception.py", line 55, in inner
    response = get_response(request)
               ^^^^^^^^^^^^^^^^^^^^^
  File "C:\Users\adm1t\AppData\Local\Programs\Python\Python312\Lib\site-packages\django\core\handlers\base.py", line 197, in _get_response
    response = wrapped_callback(request, *callback_args, **callback_kwargs)
               ^^^^^^^^^^^^^^^^^^^^^^^^^^^^^^^^^^^^^^^^^^^^^^^^^^^^^^^^^^^^
  File "C:\Users\adm1t\AppData\Local\Programs\Python\Python312\Lib\site-packages\django\contrib\auth\decorators.py", line 59, in _view_wrapper
    return view_func(request, *args, **kwargs)
           ^^^^^^^^^^^^^^^^^^^^^^^^^^^^^^^^^^^
  File "C:\Users\adm1t\Desktop\Projeto_Portal\Projeto_Portal_v2_trabalho\Migracao_Portal_v2\apps\participacao\decorators.py", line 21, in wrapper
    return view_func(request, *args, **kwargs)
           ^^^^^^^^^^^^^^^^^^^^^^^^^^^^^^^^^^^
  File "C:\Users\adm1t\Desktop\Projeto_Portal\Projeto_Portal_v2_trabalho\Migracao_Portal_v2\apps\participacao\views\participation.py", line 866, in participacao
    ).union(Funcionario.objects.filter(usuario__has_usable_password=False))))
            ^^^^^^^^^^^^^^^^^^^^^^^^^^^^^^^^^^^^^^^^^^^^^^^^^^^^^^^^^^^^^^
  File "C:\Users\adm1t\AppData\Local\Programs\Python\Python312\Lib\site-packages\django\db\models\manager.py", line 87, in manager_method
    return getattr(self.get_queryset(), name)(*args, **kwargs)
           ^^^^^^^^^^^^^^^^^^^^^^^^^^^^^^^^^^^^^^^^^^^^^^^^^^^
  File "C:\Users\adm1t\AppData\Local\Programs\Python\Python312\Lib\site-packages\django\db\models\query.py", line 1481, in filter
    return self._filter_or_exclude(False, args, kwargs)
           ^^^^^^^^^^^^^^^^^^^^^^^^^^^^^^^^^^^^^^^^^^^^
  File "C:\Users\adm1t\AppData\Local\Programs\Python\Python312\Lib\site-packages\django\db\models\query.py", line 1499, in _filter_or_exclude
    clone._filter_or_exclude_inplace(negate, args, kwargs)
  File "C:\Users\adm1t\AppData\Local\Programs\Python\Python312\Lib\site-packages\django\db\models\query.py", line 1506, in _filter_or_exclude_inplace
    self._query.add_q(Q(*args, **kwargs))
  File "C:\Users\adm1t\AppData\Local\Programs\Python\Python312\Lib\site-packages\django\db\models\sql\query.py", line 1643, in add_q
    clause, _ = self._add_q(q_object, can_reuse)
                ^^^^^^^^^^^^^^^^^^^^^^^^^^^^^^^^
  File "C:\Users\adm1t\AppData\Local\Programs\Python\Python312\Lib\site-packages\django\db\models\sql\query.py", line 1675, in _add_q
    child_clause, needed_inner = self.build_filter(
                                 ^^^^^^^^^^^^^^^^^^
  File "C:\Users\adm1t\AppData\Local\Programs\Python\Python312\Lib\site-packages\django\db\models\sql\query.py", line 1585, in build_filter
    condition = self.build_lookup(lookups, col, value)
                ^^^^^^^^^^^^^^^^^^^^^^^^^^^^^^^^^^^^^^
  File "C:\Users\adm1t\AppData\Local\Programs\Python\Python312\Lib\site-packages\django\db\models\sql\query.py", line 1406, in build_lookup
    lhs = self.try_transform(lhs, lookup_name)
          ^^^^^^^^^^^^^^^^^^^^^^^^^^^^^^^^^^^^
  File "C:\Users\adm1t\AppData\Local\Programs\Python\Python312\Lib\site-packages\django\db\models\sql\query.py", line 1455, in try_transform
    raise FieldError(
django.core.exceptions.FieldError: Unsupported lookup 'has_usable_password' for OneToOneField or join on the field not permitted.
2025-06-12 09:53:23,890 [DEBUG] Processando requisição para /participacao/participacao/ - Usuário autenticado: True
2025-06-12 09:53:23,897 [INFO] Usuário admin acessando participação
2025-06-12 09:53:23,897 [DEBUG] Último trimestre: 2025-Q2
2025-06-12 09:53:23,971 [ERROR] Internal Server Error: /participacao/participacao/
Traceback (most recent call last):
  File "C:\Users\adm1t\AppData\Local\Programs\Python\Python312\Lib\site-packages\django\core\handlers\exception.py", line 55, in inner
    response = get_response(request)
               ^^^^^^^^^^^^^^^^^^^^^
  File "C:\Users\adm1t\AppData\Local\Programs\Python\Python312\Lib\site-packages\django\core\handlers\base.py", line 197, in _get_response
    response = wrapped_callback(request, *callback_args, **callback_kwargs)
               ^^^^^^^^^^^^^^^^^^^^^^^^^^^^^^^^^^^^^^^^^^^^^^^^^^^^^^^^^^^^
  File "C:\Users\adm1t\AppData\Local\Programs\Python\Python312\Lib\site-packages\django\contrib\auth\decorators.py", line 59, in _view_wrapper
    return view_func(request, *args, **kwargs)
           ^^^^^^^^^^^^^^^^^^^^^^^^^^^^^^^^^^^
  File "C:\Users\adm1t\Desktop\Projeto_Portal\Projeto_Portal_v2_trabalho\Migracao_Portal_v2\apps\participacao\decorators.py", line 21, in wrapper
    return view_func(request, *args, **kwargs)
           ^^^^^^^^^^^^^^^^^^^^^^^^^^^^^^^^^^^
  File "C:\Users\adm1t\Desktop\Projeto_Portal\Projeto_Portal_v2_trabalho\Migracao_Portal_v2\apps\participacao\views\participation.py", line 866, in participacao
    ).union(Funcionario.objects.filter(usuario__has_usable_password=False))))
            ^^^^^^^^^^^^^^^^^^^^^^^^^^^^^^^^^^^^^^^^^^^^^^^^^^^^^^^^^^^^^^
  File "C:\Users\adm1t\AppData\Local\Programs\Python\Python312\Lib\site-packages\django\db\models\manager.py", line 87, in manager_method
    return getattr(self.get_queryset(), name)(*args, **kwargs)
           ^^^^^^^^^^^^^^^^^^^^^^^^^^^^^^^^^^^^^^^^^^^^^^^^^^^
  File "C:\Users\adm1t\AppData\Local\Programs\Python\Python312\Lib\site-packages\django\db\models\query.py", line 1481, in filter
    return self._filter_or_exclude(False, args, kwargs)
           ^^^^^^^^^^^^^^^^^^^^^^^^^^^^^^^^^^^^^^^^^^^^
  File "C:\Users\adm1t\AppData\Local\Programs\Python\Python312\Lib\site-packages\django\db\models\query.py", line 1499, in _filter_or_exclude
    clone._filter_or_exclude_inplace(negate, args, kwargs)
  File "C:\Users\adm1t\AppData\Local\Programs\Python\Python312\Lib\site-packages\django\db\models\query.py", line 1506, in _filter_or_exclude_inplace
    self._query.add_q(Q(*args, **kwargs))
  File "C:\Users\adm1t\AppData\Local\Programs\Python\Python312\Lib\site-packages\django\db\models\sql\query.py", line 1643, in add_q
    clause, _ = self._add_q(q_object, can_reuse)
                ^^^^^^^^^^^^^^^^^^^^^^^^^^^^^^^^
  File "C:\Users\adm1t\AppData\Local\Programs\Python\Python312\Lib\site-packages\django\db\models\sql\query.py", line 1675, in _add_q
    child_clause, needed_inner = self.build_filter(
                                 ^^^^^^^^^^^^^^^^^^
  File "C:\Users\adm1t\AppData\Local\Programs\Python\Python312\Lib\site-packages\django\db\models\sql\query.py", line 1585, in build_filter
    condition = self.build_lookup(lookups, col, value)
                ^^^^^^^^^^^^^^^^^^^^^^^^^^^^^^^^^^^^^^
  File "C:\Users\adm1t\AppData\Local\Programs\Python\Python312\Lib\site-packages\django\db\models\sql\query.py", line 1406, in build_lookup
    lhs = self.try_transform(lhs, lookup_name)
          ^^^^^^^^^^^^^^^^^^^^^^^^^^^^^^^^^^^^
  File "C:\Users\adm1t\AppData\Local\Programs\Python\Python312\Lib\site-packages\django\db\models\sql\query.py", line 1455, in try_transform
    raise FieldError(
django.core.exceptions.FieldError: Unsupported lookup 'has_usable_password' for OneToOneField or join on the field not permitted.
2025-06-12 09:55:41,005 [INFO] C:\Users\adm1t\Desktop\Projeto_Portal\Projeto_Portal_v2_trabalho\Migracao_Portal_v2\apps\participacao\views\participation.py changed, reloading.
2025-06-12 09:55:59,629 [INFO] Registrada tentativa de login: username=admin, IP=127.0.0.1, Maliciosa=True
2025-06-12 09:56:00,499 [INFO] Usuário admin acessando página inicial
2025-06-12 09:56:00,505 [INFO] Dados setores: {'labels': ['Admin'], 'data': [1]}
2025-06-12 09:56:00,507 [DEBUG] Usuário admin - Tipo: master_admin, Pode ver: True
2025-06-12 09:56:01,819 [DEBUG] Processando requisição para /participacao/participacao/ - Usuário autenticado: True
2025-06-12 09:56:01,824 [INFO] Usuário admin acessando participação
2025-06-12 09:56:01,824 [DEBUG] Último trimestre: 2025-Q2
2025-06-12 09:56:01,908 [ERROR] Internal Server Error: /participacao/participacao/
Traceback (most recent call last):
  File "C:\Users\adm1t\AppData\Local\Programs\Python\Python312\Lib\site-packages\django\core\handlers\exception.py", line 55, in inner
    response = get_response(request)
               ^^^^^^^^^^^^^^^^^^^^^
  File "C:\Users\adm1t\AppData\Local\Programs\Python\Python312\Lib\site-packages\django\core\handlers\base.py", line 197, in _get_response
    response = wrapped_callback(request, *callback_args, **callback_kwargs)
               ^^^^^^^^^^^^^^^^^^^^^^^^^^^^^^^^^^^^^^^^^^^^^^^^^^^^^^^^^^^^
  File "C:\Users\adm1t\AppData\Local\Programs\Python\Python312\Lib\site-packages\django\contrib\auth\decorators.py", line 59, in _view_wrapper
    return view_func(request, *args, **kwargs)
           ^^^^^^^^^^^^^^^^^^^^^^^^^^^^^^^^^^^
  File "C:\Users\adm1t\Desktop\Projeto_Portal\Projeto_Portal_v2_trabalho\Migracao_Portal_v2\apps\participacao\decorators.py", line 21, in wrapper
    return view_func(request, *args, **kwargs)
           ^^^^^^^^^^^^^^^^^^^^^^^^^^^^^^^^^^^
  File "C:\Users\adm1t\Desktop\Projeto_Portal\Projeto_Portal_v2_trabalho\Migracao_Portal_v2\apps\participacao\views\participation.py", line 861, in participacao
    usuarios_sem_senha = User.objects.filter(~Q(id__in=Funcionario.objects.values('usuario_id')) | ~Q(has_usable_password=True))
                         ^^^^^^^^^^^^^^^^^^^^^^^^^^^^^^^^^^^^^^^^^^^^^^^^^^^^^^^^^^^^^^^^^^^^^^^^^^^^^^^^^^^^^^^^^^^^^^^^^^^^^^^
  File "C:\Users\adm1t\AppData\Local\Programs\Python\Python312\Lib\site-packages\django\db\models\manager.py", line 87, in manager_method
    return getattr(self.get_queryset(), name)(*args, **kwargs)
           ^^^^^^^^^^^^^^^^^^^^^^^^^^^^^^^^^^^^^^^^^^^^^^^^^^^
  File "C:\Users\adm1t\AppData\Local\Programs\Python\Python312\Lib\site-packages\django\db\models\query.py", line 1481, in filter
    return self._filter_or_exclude(False, args, kwargs)
           ^^^^^^^^^^^^^^^^^^^^^^^^^^^^^^^^^^^^^^^^^^^^
  File "C:\Users\adm1t\AppData\Local\Programs\Python\Python312\Lib\site-packages\django\db\models\query.py", line 1499, in _filter_or_exclude
    clone._filter_or_exclude_inplace(negate, args, kwargs)
  File "C:\Users\adm1t\AppData\Local\Programs\Python\Python312\Lib\site-packages\django\db\models\query.py", line 1506, in _filter_or_exclude_inplace
    self._query.add_q(Q(*args, **kwargs))
  File "C:\Users\adm1t\AppData\Local\Programs\Python\Python312\Lib\site-packages\django\db\models\sql\query.py", line 1643, in add_q
    clause, _ = self._add_q(q_object, can_reuse)
                ^^^^^^^^^^^^^^^^^^^^^^^^^^^^^^^^
  File "C:\Users\adm1t\AppData\Local\Programs\Python\Python312\Lib\site-packages\django\db\models\sql\query.py", line 1675, in _add_q
    child_clause, needed_inner = self.build_filter(
                                 ^^^^^^^^^^^^^^^^^^
  File "C:\Users\adm1t\AppData\Local\Programs\Python\Python312\Lib\site-packages\django\db\models\sql\query.py", line 1500, in build_filter
    return self._add_q(
           ^^^^^^^^^^^^
  File "C:\Users\adm1t\AppData\Local\Programs\Python\Python312\Lib\site-packages\django\db\models\sql\query.py", line 1675, in _add_q
    child_clause, needed_inner = self.build_filter(
                                 ^^^^^^^^^^^^^^^^^^
  File "C:\Users\adm1t\AppData\Local\Programs\Python\Python312\Lib\site-packages\django\db\models\sql\query.py", line 1500, in build_filter
    return self._add_q(
           ^^^^^^^^^^^^
  File "C:\Users\adm1t\AppData\Local\Programs\Python\Python312\Lib\site-packages\django\db\models\sql\query.py", line 1675, in _add_q
    child_clause, needed_inner = self.build_filter(
                                 ^^^^^^^^^^^^^^^^^^
  File "C:\Users\adm1t\AppData\Local\Programs\Python\Python312\Lib\site-packages\django\db\models\sql\query.py", line 1523, in build_filter
    lookups, parts, reffed_expression = self.solve_lookup_type(arg, summarize)
                                        ^^^^^^^^^^^^^^^^^^^^^^^^^^^^^^^^^^^^^^
  File "C:\Users\adm1t\AppData\Local\Programs\Python\Python312\Lib\site-packages\django\db\models\sql\query.py", line 1330, in solve_lookup_type
    _, field, _, lookup_parts = self.names_to_path(lookup_splitted, self.get_meta())
                                ^^^^^^^^^^^^^^^^^^^^^^^^^^^^^^^^^^^^^^^^^^^^^^^^^^^^
  File "C:\Users\adm1t\AppData\Local\Programs\Python\Python312\Lib\site-packages\django\db\models\sql\query.py", line 1802, in names_to_path
    raise FieldError(
django.core.exceptions.FieldError: Cannot resolve keyword 'has_usable_password' into field. Choices are: date_joined, email, first_name, funcionario, groups, id, is_active, is_staff, is_superuser, last_login, last_name, logentry, loginattempt, password, user_permissions, useractionlog, username
2025-06-12 09:56:37,276 [INFO] Registrada tentativa de login: username=admin, IP=127.0.0.1, Maliciosa=True
2025-06-12 09:56:37,940 [INFO] Usuário admin acessando página inicial
2025-06-12 09:56:37,944 [INFO] Dados setores: {'labels': ['Admin'], 'data': [1]}
2025-06-12 09:56:37,946 [DEBUG] Usuário admin - Tipo: master_admin, Pode ver: True
2025-06-12 09:56:39,720 [DEBUG] Processando requisição para /participacao/configurar_participacao_setor/ - Usuário autenticado: True
2025-06-12 09:56:39,722 [INFO] Usuário admin acessando configuração de participação por setor
2025-06-12 09:56:39,772 [ERROR] Internal Server Error: /participacao/configurar_participacao_setor/
Traceback (most recent call last):
  File "C:\Users\adm1t\AppData\Local\Programs\Python\Python312\Lib\site-packages\django\template\defaulttags.py", line 1035, in find_library
    return parser.libraries[name]
           ~~~~~~~~~~~~~~~~^^^^^^
KeyError: 'filters'

During handling of the above exception, another exception occurred:

Traceback (most recent call last):
  File "C:\Users\adm1t\AppData\Local\Programs\Python\Python312\Lib\site-packages\django\core\handlers\exception.py", line 55, in inner
    response = get_response(request)
               ^^^^^^^^^^^^^^^^^^^^^
  File "C:\Users\adm1t\AppData\Local\Programs\Python\Python312\Lib\site-packages\django\core\handlers\base.py", line 197, in _get_response
    response = wrapped_callback(request, *callback_args, **callback_kwargs)
               ^^^^^^^^^^^^^^^^^^^^^^^^^^^^^^^^^^^^^^^^^^^^^^^^^^^^^^^^^^^^
  File "C:\Users\adm1t\AppData\Local\Programs\Python\Python312\Lib\site-packages\django\contrib\auth\decorators.py", line 59, in _view_wrapper
    return view_func(request, *args, **kwargs)
           ^^^^^^^^^^^^^^^^^^^^^^^^^^^^^^^^^^^
  File "C:\Users\adm1t\Desktop\Projeto_Portal\Projeto_Portal_v2_trabalho\Migracao_Portal_v2\apps\participacao\decorators.py", line 21, in wrapper
    return view_func(request, *args, **kwargs)
           ^^^^^^^^^^^^^^^^^^^^^^^^^^^^^^^^^^^
  File "C:\Users\adm1t\Desktop\Projeto_Portal\Projeto_Portal_v2_trabalho\Migracao_Portal_v2\apps\participacao\views\participation.py", line 234, in configurar_participacao_setor
    return render(request, 'participacao/configurar_participacao_setor.html', {
           ^^^^^^^^^^^^^^^^^^^^^^^^^^^^^^^^^^^^^^^^^^^^^^^^^^^^^^^^^^^^^^^^^^^^
  File "C:\Users\adm1t\AppData\Local\Programs\Python\Python312\Lib\site-packages\django\shortcuts.py", line 25, in render
    content = loader.render_to_string(template_name, context, request, using=using)
              ^^^^^^^^^^^^^^^^^^^^^^^^^^^^^^^^^^^^^^^^^^^^^^^^^^^^^^^^^^^^^^^^^^^^^
  File "C:\Users\adm1t\AppData\Local\Programs\Python\Python312\Lib\site-packages\django\template\loader.py", line 61, in render_to_string
    template = get_template(template_name, using=using)
               ^^^^^^^^^^^^^^^^^^^^^^^^^^^^^^^^^^^^^^^^
  File "C:\Users\adm1t\AppData\Local\Programs\Python\Python312\Lib\site-packages\django\template\loader.py", line 15, in get_template
    return engine.get_template(template_name)
           ^^^^^^^^^^^^^^^^^^^^^^^^^^^^^^^^^^
  File "C:\Users\adm1t\AppData\Local\Programs\Python\Python312\Lib\site-packages\django\template\backends\django.py", line 79, in get_template
    return Template(self.engine.get_template(template_name), self)
                    ^^^^^^^^^^^^^^^^^^^^^^^^^^^^^^^^^^^^^^^
  File "C:\Users\adm1t\AppData\Local\Programs\Python\Python312\Lib\site-packages\django\template\engine.py", line 177, in get_template
    template, origin = self.find_template(template_name)
                       ^^^^^^^^^^^^^^^^^^^^^^^^^^^^^^^^^
  File "C:\Users\adm1t\AppData\Local\Programs\Python\Python312\Lib\site-packages\django\template\engine.py", line 159, in find_template
    template = loader.get_template(name, skip=skip)
               ^^^^^^^^^^^^^^^^^^^^^^^^^^^^^^^^^^^^
  File "C:\Users\adm1t\AppData\Local\Programs\Python\Python312\Lib\site-packages\django\template\loaders\cached.py", line 57, in get_template
    template = super().get_template(template_name, skip)
               ^^^^^^^^^^^^^^^^^^^^^^^^^^^^^^^^^^^^^^^^^
  File "C:\Users\adm1t\AppData\Local\Programs\Python\Python312\Lib\site-packages\django\template\loaders\base.py", line 28, in get_template
    return Template(
           ^^^^^^^^^
  File "C:\Users\adm1t\AppData\Local\Programs\Python\Python312\Lib\site-packages\django\template\base.py", line 154, in __init__
    self.nodelist = self.compile_nodelist()
                    ^^^^^^^^^^^^^^^^^^^^^^^
  File "C:\Users\adm1t\AppData\Local\Programs\Python\Python312\Lib\site-packages\django\template\base.py", line 196, in compile_nodelist
    nodelist = parser.parse()
               ^^^^^^^^^^^^^^
  File "C:\Users\adm1t\AppData\Local\Programs\Python\Python312\Lib\site-packages\django\template\base.py", line 518, in parse
    raise self.error(token, e)
  File "C:\Users\adm1t\AppData\Local\Programs\Python\Python312\Lib\site-packages\django\template\base.py", line 516, in parse
    compiled_result = compile_func(self, token)
                      ^^^^^^^^^^^^^^^^^^^^^^^^^
  File "C:\Users\adm1t\AppData\Local\Programs\Python\Python312\Lib\site-packages\django\template\defaulttags.py", line 1097, in load
    lib = find_library(parser, name)
          ^^^^^^^^^^^^^^^^^^^^^^^^^^
  File "C:\Users\adm1t\AppData\Local\Programs\Python\Python312\Lib\site-packages\django\template\defaulttags.py", line 1037, in find_library
    raise TemplateSyntaxError(
django.template.exceptions.TemplateSyntaxError: 'filters' is not a registered tag library. Must be one of:
admin_list
admin_modify
admin_urls
cache
i18n
l10n
log
static
tz
2025-06-12 10:00:16,465 [INFO] C:\Users\adm1t\Desktop\Projeto_Portal\Projeto_Portal_v2_trabalho\Migracao_Portal_v2\Projeto_Portal_v2\settings.py changed, reloading.
2025-06-12 10:00:57,491 [INFO] C:\Users\adm1t\Desktop\Projeto_Portal\Projeto_Portal_v2_trabalho\Migracao_Portal_v2\apps\participacao\templates\participacao\templatetags\custom_filters.py changed, reloading.
2025-06-12 10:01:13,354 [INFO] Registrada tentativa de login: username=admin, IP=127.0.0.1, Maliciosa=True
2025-06-12 10:01:14,197 [INFO] Usuário admin acessando página inicial
2025-06-12 10:01:14,202 [INFO] Dados setores: {'labels': ['Admin'], 'data': [1]}
2025-06-12 10:01:14,204 [DEBUG] Usuário admin - Tipo: master_admin, Pode ver: True
2025-06-12 10:01:15,459 [DEBUG] Processando requisição para /participacao/participacao/ - Usuário autenticado: True
2025-06-12 10:01:15,462 [INFO] Usuário admin acessando participação
2025-06-12 10:01:15,462 [DEBUG] Último trimestre: 2025-Q2
2025-06-12 10:01:15,534 [ERROR] Internal Server Error: /participacao/participacao/
Traceback (most recent call last):
  File "C:\Users\adm1t\AppData\Local\Programs\Python\Python312\Lib\site-packages\django\core\handlers\exception.py", line 55, in inner
    response = get_response(request)
               ^^^^^^^^^^^^^^^^^^^^^
  File "C:\Users\adm1t\AppData\Local\Programs\Python\Python312\Lib\site-packages\django\core\handlers\base.py", line 197, in _get_response
    response = wrapped_callback(request, *callback_args, **callback_kwargs)
               ^^^^^^^^^^^^^^^^^^^^^^^^^^^^^^^^^^^^^^^^^^^^^^^^^^^^^^^^^^^^
  File "C:\Users\adm1t\AppData\Local\Programs\Python\Python312\Lib\site-packages\django\contrib\auth\decorators.py", line 59, in _view_wrapper
    return view_func(request, *args, **kwargs)
           ^^^^^^^^^^^^^^^^^^^^^^^^^^^^^^^^^^^
  File "C:\Users\adm1t\Desktop\Projeto_Portal\Projeto_Portal_v2_trabalho\Migracao_Portal_v2\apps\participacao\decorators.py", line 21, in wrapper
    return view_func(request, *args, **kwargs)
           ^^^^^^^^^^^^^^^^^^^^^^^^^^^^^^^^^^^
  File "C:\Users\adm1t\Desktop\Projeto_Portal\Projeto_Portal_v2_trabalho\Migracao_Portal_v2\apps\participacao\views\participation.py", line 861, in participacao
    usuarios_sem_senha = User.objects.filter(~Q(id__in=Funcionario.objects.values('usuario_id')) | ~Q(has_usable_password=True))
                         ^^^^^^^^^^^^^^^^^^^^^^^^^^^^^^^^^^^^^^^^^^^^^^^^^^^^^^^^^^^^^^^^^^^^^^^^^^^^^^^^^^^^^^^^^^^^^^^^^^^^^^^
  File "C:\Users\adm1t\AppData\Local\Programs\Python\Python312\Lib\site-packages\django\db\models\manager.py", line 87, in manager_method
    return getattr(self.get_queryset(), name)(*args, **kwargs)
           ^^^^^^^^^^^^^^^^^^^^^^^^^^^^^^^^^^^^^^^^^^^^^^^^^^^
  File "C:\Users\adm1t\AppData\Local\Programs\Python\Python312\Lib\site-packages\django\db\models\query.py", line 1481, in filter
    return self._filter_or_exclude(False, args, kwargs)
           ^^^^^^^^^^^^^^^^^^^^^^^^^^^^^^^^^^^^^^^^^^^^
  File "C:\Users\adm1t\AppData\Local\Programs\Python\Python312\Lib\site-packages\django\db\models\query.py", line 1499, in _filter_or_exclude
    clone._filter_or_exclude_inplace(negate, args, kwargs)
  File "C:\Users\adm1t\AppData\Local\Programs\Python\Python312\Lib\site-packages\django\db\models\query.py", line 1506, in _filter_or_exclude_inplace
    self._query.add_q(Q(*args, **kwargs))
  File "C:\Users\adm1t\AppData\Local\Programs\Python\Python312\Lib\site-packages\django\db\models\sql\query.py", line 1643, in add_q
    clause, _ = self._add_q(q_object, can_reuse)
                ^^^^^^^^^^^^^^^^^^^^^^^^^^^^^^^^
  File "C:\Users\adm1t\AppData\Local\Programs\Python\Python312\Lib\site-packages\django\db\models\sql\query.py", line 1675, in _add_q
    child_clause, needed_inner = self.build_filter(
                                 ^^^^^^^^^^^^^^^^^^
  File "C:\Users\adm1t\AppData\Local\Programs\Python\Python312\Lib\site-packages\django\db\models\sql\query.py", line 1500, in build_filter
    return self._add_q(
           ^^^^^^^^^^^^
  File "C:\Users\adm1t\AppData\Local\Programs\Python\Python312\Lib\site-packages\django\db\models\sql\query.py", line 1675, in _add_q
    child_clause, needed_inner = self.build_filter(
                                 ^^^^^^^^^^^^^^^^^^
  File "C:\Users\adm1t\AppData\Local\Programs\Python\Python312\Lib\site-packages\django\db\models\sql\query.py", line 1500, in build_filter
    return self._add_q(
           ^^^^^^^^^^^^
  File "C:\Users\adm1t\AppData\Local\Programs\Python\Python312\Lib\site-packages\django\db\models\sql\query.py", line 1675, in _add_q
    child_clause, needed_inner = self.build_filter(
                                 ^^^^^^^^^^^^^^^^^^
  File "C:\Users\adm1t\AppData\Local\Programs\Python\Python312\Lib\site-packages\django\db\models\sql\query.py", line 1523, in build_filter
    lookups, parts, reffed_expression = self.solve_lookup_type(arg, summarize)
                                        ^^^^^^^^^^^^^^^^^^^^^^^^^^^^^^^^^^^^^^
  File "C:\Users\adm1t\AppData\Local\Programs\Python\Python312\Lib\site-packages\django\db\models\sql\query.py", line 1330, in solve_lookup_type
    _, field, _, lookup_parts = self.names_to_path(lookup_splitted, self.get_meta())
                                ^^^^^^^^^^^^^^^^^^^^^^^^^^^^^^^^^^^^^^^^^^^^^^^^^^^^
  File "C:\Users\adm1t\AppData\Local\Programs\Python\Python312\Lib\site-packages\django\db\models\sql\query.py", line 1802, in names_to_path
    raise FieldError(
django.core.exceptions.FieldError: Cannot resolve keyword 'has_usable_password' into field. Choices are: date_joined, email, first_name, funcionario, groups, id, is_active, is_staff, is_superuser, last_login, last_name, logentry, loginattempt, password, user_permissions, useractionlog, username
2025-06-12 10:04:17,921 [INFO] Registrada tentativa de login: username=admin, IP=127.0.0.1, Maliciosa=True
2025-06-12 10:04:18,673 [INFO] Usuário admin acessando página inicial
2025-06-12 10:04:18,677 [INFO] Dados setores: {'labels': ['Admin'], 'data': [1]}
2025-06-12 10:04:18,679 [DEBUG] Usuário admin - Tipo: master_admin, Pode ver: True
2025-06-12 10:04:19,773 [DEBUG] Processando requisição para /participacao/participacao/ - Usuário autenticado: True
2025-06-12 10:04:19,778 [INFO] Usuário admin acessando participação
2025-06-12 10:04:19,779 [DEBUG] Último trimestre: 2025-Q2
2025-06-12 10:04:19,798 [DEBUG] Dados enviados: page_obj=[]
2025-06-12 10:04:19,892 [ERROR] Internal Server Error: /participacao/participacao/
Traceback (most recent call last):
  File "C:\Users\adm1t\AppData\Local\Programs\Python\Python312\Lib\site-packages\django\template\defaulttags.py", line 1035, in find_library
    return parser.libraries[name]
           ~~~~~~~~~~~~~~~~^^^^^^
KeyError: 'filters'

During handling of the above exception, another exception occurred:

Traceback (most recent call last):
  File "C:\Users\adm1t\AppData\Local\Programs\Python\Python312\Lib\site-packages\django\core\handlers\exception.py", line 55, in inner
    response = get_response(request)
               ^^^^^^^^^^^^^^^^^^^^^
  File "C:\Users\adm1t\AppData\Local\Programs\Python\Python312\Lib\site-packages\django\core\handlers\base.py", line 197, in _get_response
    response = wrapped_callback(request, *callback_args, **callback_kwargs)
               ^^^^^^^^^^^^^^^^^^^^^^^^^^^^^^^^^^^^^^^^^^^^^^^^^^^^^^^^^^^^
  File "C:\Users\adm1t\AppData\Local\Programs\Python\Python312\Lib\site-packages\django\contrib\auth\decorators.py", line 59, in _view_wrapper
    return view_func(request, *args, **kwargs)
           ^^^^^^^^^^^^^^^^^^^^^^^^^^^^^^^^^^^
  File "C:\Users\adm1t\Desktop\Projeto_Portal\Projeto_Portal_v2_trabalho\Migracao_Portal_v2\apps\participacao\decorators.py", line 21, in wrapper
    return view_func(request, *args, **kwargs)
           ^^^^^^^^^^^^^^^^^^^^^^^^^^^^^^^^^^^
  File "C:\Users\adm1t\Desktop\Projeto_Portal\Projeto_Portal_v2_trabalho\Migracao_Portal_v2\apps\participacao\views\participation.py", line 876, in participacao
    return render(request, 'participacao/participacao.html', {
           ^^^^^^^^^^^^^^^^^^^^^^^^^^^^^^^^^^^^^^^^^^^^^^^^^^^
  File "C:\Users\adm1t\AppData\Local\Programs\Python\Python312\Lib\site-packages\django\shortcuts.py", line 25, in render
    content = loader.render_to_string(template_name, context, request, using=using)
              ^^^^^^^^^^^^^^^^^^^^^^^^^^^^^^^^^^^^^^^^^^^^^^^^^^^^^^^^^^^^^^^^^^^^^
  File "C:\Users\adm1t\AppData\Local\Programs\Python\Python312\Lib\site-packages\django\template\loader.py", line 61, in render_to_string
    template = get_template(template_name, using=using)
               ^^^^^^^^^^^^^^^^^^^^^^^^^^^^^^^^^^^^^^^^
  File "C:\Users\adm1t\AppData\Local\Programs\Python\Python312\Lib\site-packages\django\template\loader.py", line 15, in get_template
    return engine.get_template(template_name)
           ^^^^^^^^^^^^^^^^^^^^^^^^^^^^^^^^^^
  File "C:\Users\adm1t\AppData\Local\Programs\Python\Python312\Lib\site-packages\django\template\backends\django.py", line 79, in get_template
    return Template(self.engine.get_template(template_name), self)
                    ^^^^^^^^^^^^^^^^^^^^^^^^^^^^^^^^^^^^^^^
  File "C:\Users\adm1t\AppData\Local\Programs\Python\Python312\Lib\site-packages\django\template\engine.py", line 177, in get_template
    template, origin = self.find_template(template_name)
                       ^^^^^^^^^^^^^^^^^^^^^^^^^^^^^^^^^
  File "C:\Users\adm1t\AppData\Local\Programs\Python\Python312\Lib\site-packages\django\template\engine.py", line 159, in find_template
    template = loader.get_template(name, skip=skip)
               ^^^^^^^^^^^^^^^^^^^^^^^^^^^^^^^^^^^^
  File "C:\Users\adm1t\AppData\Local\Programs\Python\Python312\Lib\site-packages\django\template\loaders\cached.py", line 57, in get_template
    template = super().get_template(template_name, skip)
               ^^^^^^^^^^^^^^^^^^^^^^^^^^^^^^^^^^^^^^^^^
  File "C:\Users\adm1t\AppData\Local\Programs\Python\Python312\Lib\site-packages\django\template\loaders\base.py", line 28, in get_template
    return Template(
           ^^^^^^^^^
  File "C:\Users\adm1t\AppData\Local\Programs\Python\Python312\Lib\site-packages\django\template\base.py", line 154, in __init__
    self.nodelist = self.compile_nodelist()
                    ^^^^^^^^^^^^^^^^^^^^^^^
  File "C:\Users\adm1t\AppData\Local\Programs\Python\Python312\Lib\site-packages\django\template\base.py", line 196, in compile_nodelist
    nodelist = parser.parse()
               ^^^^^^^^^^^^^^
  File "C:\Users\adm1t\AppData\Local\Programs\Python\Python312\Lib\site-packages\django\template\base.py", line 518, in parse
    raise self.error(token, e)
  File "C:\Users\adm1t\AppData\Local\Programs\Python\Python312\Lib\site-packages\django\template\base.py", line 516, in parse
    compiled_result = compile_func(self, token)
                      ^^^^^^^^^^^^^^^^^^^^^^^^^
  File "C:\Users\adm1t\AppData\Local\Programs\Python\Python312\Lib\site-packages\django\template\defaulttags.py", line 1097, in load
    lib = find_library(parser, name)
          ^^^^^^^^^^^^^^^^^^^^^^^^^^
  File "C:\Users\adm1t\AppData\Local\Programs\Python\Python312\Lib\site-packages\django\template\defaulttags.py", line 1037, in find_library
    raise TemplateSyntaxError(
django.template.exceptions.TemplateSyntaxError: 'filters' is not a registered tag library. Must be one of:
admin_list
admin_modify
admin_urls
cache
i18n
l10n
log
static
tz
2025-06-12 10:07:14,177 [INFO] C:\Users\adm1t\Desktop\Projeto_Portal\Projeto_Portal_v2_trabalho\Migracao_Portal_v2\apps\participacao\templates\participacao\templatetags\filters.py changed, reloading.
2025-06-12 10:09:47,045 [INFO] C:\Users\adm1t\Desktop\Projeto_Portal\Projeto_Portal_v2_trabalho\Migracao_Portal_v2\apps\participacao\templates\participacao\templatetags\filters.py changed, reloading.
2025-06-12 10:10:24,331 [INFO] Registrada tentativa de login: username=admin, IP=127.0.0.1, Maliciosa=True
2025-06-12 10:10:25,138 [INFO] Usuário admin acessando página inicial
2025-06-12 10:10:25,143 [INFO] Dados setores: {'labels': ['Admin'], 'data': [1]}
2025-06-12 10:10:25,144 [DEBUG] Usuário admin - Tipo: master_admin, Pode ver: True
2025-06-12 10:10:26,441 [DEBUG] Processando requisição para /participacao/participacao/ - Usuário autenticado: True
2025-06-12 10:10:26,443 [INFO] Usuário admin acessando participação
2025-06-12 10:10:26,443 [DEBUG] Último trimestre: 2025-Q2
2025-06-12 10:10:26,456 [DEBUG] Dados enviados: page_obj=[]
2025-06-12 10:10:26,528 [ERROR] Internal Server Error: /participacao/participacao/
Traceback (most recent call last):
  File "C:\Users\adm1t\AppData\Local\Programs\Python\Python312\Lib\site-packages\django\template\defaulttags.py", line 1035, in find_library
    return parser.libraries[name]
           ~~~~~~~~~~~~~~~~^^^^^^
KeyError: 'filters'

During handling of the above exception, another exception occurred:

Traceback (most recent call last):
  File "C:\Users\adm1t\AppData\Local\Programs\Python\Python312\Lib\site-packages\django\core\handlers\exception.py", line 55, in inner
    response = get_response(request)
               ^^^^^^^^^^^^^^^^^^^^^
  File "C:\Users\adm1t\AppData\Local\Programs\Python\Python312\Lib\site-packages\django\core\handlers\base.py", line 197, in _get_response
    response = wrapped_callback(request, *callback_args, **callback_kwargs)
               ^^^^^^^^^^^^^^^^^^^^^^^^^^^^^^^^^^^^^^^^^^^^^^^^^^^^^^^^^^^^
  File "C:\Users\adm1t\AppData\Local\Programs\Python\Python312\Lib\site-packages\django\contrib\auth\decorators.py", line 59, in _view_wrapper
    return view_func(request, *args, **kwargs)
           ^^^^^^^^^^^^^^^^^^^^^^^^^^^^^^^^^^^
  File "C:\Users\adm1t\Desktop\Projeto_Portal\Projeto_Portal_v2_trabalho\Migracao_Portal_v2\apps\participacao\decorators.py", line 21, in wrapper
    return view_func(request, *args, **kwargs)
           ^^^^^^^^^^^^^^^^^^^^^^^^^^^^^^^^^^^
  File "C:\Users\adm1t\Desktop\Projeto_Portal\Projeto_Portal_v2_trabalho\Migracao_Portal_v2\apps\participacao\views\participation.py", line 876, in participacao
    return render(request, 'participacao/participacao.html', {
           ^^^^^^^^^^^^^^^^^^^^^^^^^^^^^^^^^^^^^^^^^^^^^^^^^^^
  File "C:\Users\adm1t\AppData\Local\Programs\Python\Python312\Lib\site-packages\django\shortcuts.py", line 25, in render
    content = loader.render_to_string(template_name, context, request, using=using)
              ^^^^^^^^^^^^^^^^^^^^^^^^^^^^^^^^^^^^^^^^^^^^^^^^^^^^^^^^^^^^^^^^^^^^^
  File "C:\Users\adm1t\AppData\Local\Programs\Python\Python312\Lib\site-packages\django\template\loader.py", line 61, in render_to_string
    template = get_template(template_name, using=using)
               ^^^^^^^^^^^^^^^^^^^^^^^^^^^^^^^^^^^^^^^^
  File "C:\Users\adm1t\AppData\Local\Programs\Python\Python312\Lib\site-packages\django\template\loader.py", line 15, in get_template
    return engine.get_template(template_name)
           ^^^^^^^^^^^^^^^^^^^^^^^^^^^^^^^^^^
  File "C:\Users\adm1t\AppData\Local\Programs\Python\Python312\Lib\site-packages\django\template\backends\django.py", line 79, in get_template
    return Template(self.engine.get_template(template_name), self)
                    ^^^^^^^^^^^^^^^^^^^^^^^^^^^^^^^^^^^^^^^
  File "C:\Users\adm1t\AppData\Local\Programs\Python\Python312\Lib\site-packages\django\template\engine.py", line 177, in get_template
    template, origin = self.find_template(template_name)
                       ^^^^^^^^^^^^^^^^^^^^^^^^^^^^^^^^^
  File "C:\Users\adm1t\AppData\Local\Programs\Python\Python312\Lib\site-packages\django\template\engine.py", line 159, in find_template
    template = loader.get_template(name, skip=skip)
               ^^^^^^^^^^^^^^^^^^^^^^^^^^^^^^^^^^^^
  File "C:\Users\adm1t\AppData\Local\Programs\Python\Python312\Lib\site-packages\django\template\loaders\cached.py", line 57, in get_template
    template = super().get_template(template_name, skip)
               ^^^^^^^^^^^^^^^^^^^^^^^^^^^^^^^^^^^^^^^^^
  File "C:\Users\adm1t\AppData\Local\Programs\Python\Python312\Lib\site-packages\django\template\loaders\base.py", line 28, in get_template
    return Template(
           ^^^^^^^^^
  File "C:\Users\adm1t\AppData\Local\Programs\Python\Python312\Lib\site-packages\django\template\base.py", line 154, in __init__
    self.nodelist = self.compile_nodelist()
                    ^^^^^^^^^^^^^^^^^^^^^^^
  File "C:\Users\adm1t\AppData\Local\Programs\Python\Python312\Lib\site-packages\django\template\base.py", line 196, in compile_nodelist
    nodelist = parser.parse()
               ^^^^^^^^^^^^^^
  File "C:\Users\adm1t\AppData\Local\Programs\Python\Python312\Lib\site-packages\django\template\base.py", line 518, in parse
    raise self.error(token, e)
  File "C:\Users\adm1t\AppData\Local\Programs\Python\Python312\Lib\site-packages\django\template\base.py", line 516, in parse
    compiled_result = compile_func(self, token)
                      ^^^^^^^^^^^^^^^^^^^^^^^^^
  File "C:\Users\adm1t\AppData\Local\Programs\Python\Python312\Lib\site-packages\django\template\defaulttags.py", line 1097, in load
    lib = find_library(parser, name)
          ^^^^^^^^^^^^^^^^^^^^^^^^^^
  File "C:\Users\adm1t\AppData\Local\Programs\Python\Python312\Lib\site-packages\django\template\defaulttags.py", line 1037, in find_library
    raise TemplateSyntaxError(
django.template.exceptions.TemplateSyntaxError: 'filters' is not a registered tag library. Must be one of:
admin_list
admin_modify
admin_urls
cache
i18n
l10n
log
static
tz
2025-06-12 10:16:07,997 [INFO] C:\Users\adm1t\Desktop\Projeto_Portal\Projeto_Portal_v2_trabalho\Migracao_Portal_v2\apps\participacao\templates\participacao\templatetags\filters.py changed, reloading.
2025-06-12 10:16:49,166 [INFO] Registrada tentativa de login: username=admin, IP=127.0.0.1, Maliciosa=True
2025-06-12 10:16:49,918 [INFO] Usuário admin acessando página inicial
2025-06-12 10:16:49,923 [INFO] Dados setores: {'labels': ['Admin'], 'data': [1]}
2025-06-12 10:16:49,926 [DEBUG] Usuário admin - Tipo: master_admin, Pode ver: True
2025-06-12 10:16:51,199 [DEBUG] Processando requisição para /participacao/participacao/ - Usuário autenticado: True
2025-06-12 10:16:51,202 [INFO] Usuário admin acessando participação
2025-06-12 10:16:51,202 [DEBUG] Último trimestre: 2025-Q2
2025-06-12 10:16:51,215 [DEBUG] Dados enviados: page_obj=[]
2025-06-12 10:16:51,293 [ERROR] Internal Server Error: /participacao/participacao/
Traceback (most recent call last):
  File "C:\Users\adm1t\AppData\Local\Programs\Python\Python312\Lib\site-packages\django\template\defaulttags.py", line 1035, in find_library
    return parser.libraries[name]
           ~~~~~~~~~~~~~~~~^^^^^^
KeyError: 'filters'

During handling of the above exception, another exception occurred:

Traceback (most recent call last):
  File "C:\Users\adm1t\AppData\Local\Programs\Python\Python312\Lib\site-packages\django\core\handlers\exception.py", line 55, in inner
    response = get_response(request)
               ^^^^^^^^^^^^^^^^^^^^^
  File "C:\Users\adm1t\AppData\Local\Programs\Python\Python312\Lib\site-packages\django\core\handlers\base.py", line 197, in _get_response
    response = wrapped_callback(request, *callback_args, **callback_kwargs)
               ^^^^^^^^^^^^^^^^^^^^^^^^^^^^^^^^^^^^^^^^^^^^^^^^^^^^^^^^^^^^
  File "C:\Users\adm1t\AppData\Local\Programs\Python\Python312\Lib\site-packages\django\contrib\auth\decorators.py", line 59, in _view_wrapper
    return view_func(request, *args, **kwargs)
           ^^^^^^^^^^^^^^^^^^^^^^^^^^^^^^^^^^^
  File "C:\Users\adm1t\Desktop\Projeto_Portal\Projeto_Portal_v2_trabalho\Migracao_Portal_v2\apps\participacao\decorators.py", line 21, in wrapper
    return view_func(request, *args, **kwargs)
           ^^^^^^^^^^^^^^^^^^^^^^^^^^^^^^^^^^^
  File "C:\Users\adm1t\Desktop\Projeto_Portal\Projeto_Portal_v2_trabalho\Migracao_Portal_v2\apps\participacao\views\participation.py", line 876, in participacao
    return render(request, 'participacao/participacao.html', {
           ^^^^^^^^^^^^^^^^^^^^^^^^^^^^^^^^^^^^^^^^^^^^^^^^^^^
  File "C:\Users\adm1t\AppData\Local\Programs\Python\Python312\Lib\site-packages\django\shortcuts.py", line 25, in render
    content = loader.render_to_string(template_name, context, request, using=using)
              ^^^^^^^^^^^^^^^^^^^^^^^^^^^^^^^^^^^^^^^^^^^^^^^^^^^^^^^^^^^^^^^^^^^^^
  File "C:\Users\adm1t\AppData\Local\Programs\Python\Python312\Lib\site-packages\django\template\loader.py", line 61, in render_to_string
    template = get_template(template_name, using=using)
               ^^^^^^^^^^^^^^^^^^^^^^^^^^^^^^^^^^^^^^^^
  File "C:\Users\adm1t\AppData\Local\Programs\Python\Python312\Lib\site-packages\django\template\loader.py", line 15, in get_template
    return engine.get_template(template_name)
           ^^^^^^^^^^^^^^^^^^^^^^^^^^^^^^^^^^
  File "C:\Users\adm1t\AppData\Local\Programs\Python\Python312\Lib\site-packages\django\template\backends\django.py", line 79, in get_template
    return Template(self.engine.get_template(template_name), self)
                    ^^^^^^^^^^^^^^^^^^^^^^^^^^^^^^^^^^^^^^^
  File "C:\Users\adm1t\AppData\Local\Programs\Python\Python312\Lib\site-packages\django\template\engine.py", line 177, in get_template
    template, origin = self.find_template(template_name)
                       ^^^^^^^^^^^^^^^^^^^^^^^^^^^^^^^^^
  File "C:\Users\adm1t\AppData\Local\Programs\Python\Python312\Lib\site-packages\django\template\engine.py", line 159, in find_template
    template = loader.get_template(name, skip=skip)
               ^^^^^^^^^^^^^^^^^^^^^^^^^^^^^^^^^^^^
  File "C:\Users\adm1t\AppData\Local\Programs\Python\Python312\Lib\site-packages\django\template\loaders\cached.py", line 57, in get_template
    template = super().get_template(template_name, skip)
               ^^^^^^^^^^^^^^^^^^^^^^^^^^^^^^^^^^^^^^^^^
  File "C:\Users\adm1t\AppData\Local\Programs\Python\Python312\Lib\site-packages\django\template\loaders\base.py", line 28, in get_template
    return Template(
           ^^^^^^^^^
  File "C:\Users\adm1t\AppData\Local\Programs\Python\Python312\Lib\site-packages\django\template\base.py", line 154, in __init__
    self.nodelist = self.compile_nodelist()
                    ^^^^^^^^^^^^^^^^^^^^^^^
  File "C:\Users\adm1t\AppData\Local\Programs\Python\Python312\Lib\site-packages\django\template\base.py", line 196, in compile_nodelist
    nodelist = parser.parse()
               ^^^^^^^^^^^^^^
  File "C:\Users\adm1t\AppData\Local\Programs\Python\Python312\Lib\site-packages\django\template\base.py", line 518, in parse
    raise self.error(token, e)
  File "C:\Users\adm1t\AppData\Local\Programs\Python\Python312\Lib\site-packages\django\template\base.py", line 516, in parse
    compiled_result = compile_func(self, token)
                      ^^^^^^^^^^^^^^^^^^^^^^^^^
  File "C:\Users\adm1t\AppData\Local\Programs\Python\Python312\Lib\site-packages\django\template\defaulttags.py", line 1097, in load
    lib = find_library(parser, name)
          ^^^^^^^^^^^^^^^^^^^^^^^^^^
  File "C:\Users\adm1t\AppData\Local\Programs\Python\Python312\Lib\site-packages\django\template\defaulttags.py", line 1037, in find_library
    raise TemplateSyntaxError(
django.template.exceptions.TemplateSyntaxError: 'filters' is not a registered tag library. Must be one of:
admin_list
admin_modify
admin_urls
cache
i18n
l10n
log
static
tz
2025-06-12 10:20:09,040 [INFO] C:\Users\adm1t\Desktop\Projeto_Portal\Projeto_Portal_v2_trabalho\Migracao_Portal_v2\apps\participacao\templates\participacao\templatetags\filters.py changed, reloading.
2025-06-12 10:21:05,772 [INFO] C:\Users\adm1t\Desktop\Projeto_Portal\Projeto_Portal_v2_trabalho\Migracao_Portal_v2\apps\participacao\templates\participacao\templatetags\filters.py changed, reloading.
2025-06-12 10:21:34,917 [INFO] Registrada tentativa de login: username=admin, IP=127.0.0.1, Maliciosa=True
2025-06-12 10:21:35,671 [INFO] Usuário admin acessando página inicial
2025-06-12 10:21:35,676 [INFO] Dados setores: {'labels': ['Admin'], 'data': [1]}
2025-06-12 10:21:35,678 [DEBUG] Usuário admin - Tipo: master_admin, Pode ver: True
2025-06-12 10:21:36,997 [DEBUG] Processando requisição para /participacao/participacao/ - Usuário autenticado: True
2025-06-12 10:21:37,000 [INFO] Usuário admin acessando participação
2025-06-12 10:21:37,000 [DEBUG] Último trimestre: 2025-Q2
2025-06-12 10:21:37,010 [DEBUG] Dados enviados: page_obj=[]
2025-06-12 10:21:37,074 [ERROR] Internal Server Error: /participacao/participacao/
Traceback (most recent call last):
  File "C:\Users\adm1t\AppData\Local\Programs\Python\Python312\Lib\site-packages\django\template\defaulttags.py", line 1035, in find_library
    return parser.libraries[name]
           ~~~~~~~~~~~~~~~~^^^^^^
KeyError: 'filters'

During handling of the above exception, another exception occurred:

Traceback (most recent call last):
  File "C:\Users\adm1t\AppData\Local\Programs\Python\Python312\Lib\site-packages\django\core\handlers\exception.py", line 55, in inner
    response = get_response(request)
               ^^^^^^^^^^^^^^^^^^^^^
  File "C:\Users\adm1t\AppData\Local\Programs\Python\Python312\Lib\site-packages\django\core\handlers\base.py", line 197, in _get_response
    response = wrapped_callback(request, *callback_args, **callback_kwargs)
               ^^^^^^^^^^^^^^^^^^^^^^^^^^^^^^^^^^^^^^^^^^^^^^^^^^^^^^^^^^^^
  File "C:\Users\adm1t\AppData\Local\Programs\Python\Python312\Lib\site-packages\django\contrib\auth\decorators.py", line 59, in _view_wrapper
    return view_func(request, *args, **kwargs)
           ^^^^^^^^^^^^^^^^^^^^^^^^^^^^^^^^^^^
  File "C:\Users\adm1t\Desktop\Projeto_Portal\Projeto_Portal_v2_trabalho\Migracao_Portal_v2\apps\participacao\decorators.py", line 21, in wrapper
    return view_func(request, *args, **kwargs)
           ^^^^^^^^^^^^^^^^^^^^^^^^^^^^^^^^^^^
  File "C:\Users\adm1t\Desktop\Projeto_Portal\Projeto_Portal_v2_trabalho\Migracao_Portal_v2\apps\participacao\views\participation.py", line 876, in participacao
    return render(request, 'participacao/participacao.html', {
           ^^^^^^^^^^^^^^^^^^^^^^^^^^^^^^^^^^^^^^^^^^^^^^^^^^^
  File "C:\Users\adm1t\AppData\Local\Programs\Python\Python312\Lib\site-packages\django\shortcuts.py", line 25, in render
    content = loader.render_to_string(template_name, context, request, using=using)
              ^^^^^^^^^^^^^^^^^^^^^^^^^^^^^^^^^^^^^^^^^^^^^^^^^^^^^^^^^^^^^^^^^^^^^
  File "C:\Users\adm1t\AppData\Local\Programs\Python\Python312\Lib\site-packages\django\template\loader.py", line 61, in render_to_string
    template = get_template(template_name, using=using)
               ^^^^^^^^^^^^^^^^^^^^^^^^^^^^^^^^^^^^^^^^
  File "C:\Users\adm1t\AppData\Local\Programs\Python\Python312\Lib\site-packages\django\template\loader.py", line 15, in get_template
    return engine.get_template(template_name)
           ^^^^^^^^^^^^^^^^^^^^^^^^^^^^^^^^^^
  File "C:\Users\adm1t\AppData\Local\Programs\Python\Python312\Lib\site-packages\django\template\backends\django.py", line 79, in get_template
    return Template(self.engine.get_template(template_name), self)
                    ^^^^^^^^^^^^^^^^^^^^^^^^^^^^^^^^^^^^^^^
  File "C:\Users\adm1t\AppData\Local\Programs\Python\Python312\Lib\site-packages\django\template\engine.py", line 177, in get_template
    template, origin = self.find_template(template_name)
                       ^^^^^^^^^^^^^^^^^^^^^^^^^^^^^^^^^
  File "C:\Users\adm1t\AppData\Local\Programs\Python\Python312\Lib\site-packages\django\template\engine.py", line 159, in find_template
    template = loader.get_template(name, skip=skip)
               ^^^^^^^^^^^^^^^^^^^^^^^^^^^^^^^^^^^^
  File "C:\Users\adm1t\AppData\Local\Programs\Python\Python312\Lib\site-packages\django\template\loaders\cached.py", line 57, in get_template
    template = super().get_template(template_name, skip)
               ^^^^^^^^^^^^^^^^^^^^^^^^^^^^^^^^^^^^^^^^^
  File "C:\Users\adm1t\AppData\Local\Programs\Python\Python312\Lib\site-packages\django\template\loaders\base.py", line 28, in get_template
    return Template(
           ^^^^^^^^^
  File "C:\Users\adm1t\AppData\Local\Programs\Python\Python312\Lib\site-packages\django\template\base.py", line 154, in __init__
    self.nodelist = self.compile_nodelist()
                    ^^^^^^^^^^^^^^^^^^^^^^^
  File "C:\Users\adm1t\AppData\Local\Programs\Python\Python312\Lib\site-packages\django\template\base.py", line 196, in compile_nodelist
    nodelist = parser.parse()
               ^^^^^^^^^^^^^^
  File "C:\Users\adm1t\AppData\Local\Programs\Python\Python312\Lib\site-packages\django\template\base.py", line 518, in parse
    raise self.error(token, e)
  File "C:\Users\adm1t\AppData\Local\Programs\Python\Python312\Lib\site-packages\django\template\base.py", line 516, in parse
    compiled_result = compile_func(self, token)
                      ^^^^^^^^^^^^^^^^^^^^^^^^^
  File "C:\Users\adm1t\AppData\Local\Programs\Python\Python312\Lib\site-packages\django\template\defaulttags.py", line 1097, in load
    lib = find_library(parser, name)
          ^^^^^^^^^^^^^^^^^^^^^^^^^^
  File "C:\Users\adm1t\AppData\Local\Programs\Python\Python312\Lib\site-packages\django\template\defaulttags.py", line 1037, in find_library
    raise TemplateSyntaxError(
django.template.exceptions.TemplateSyntaxError: 'filters' is not a registered tag library. Must be one of:
admin_list
admin_modify
admin_urls
cache
i18n
l10n
log
static
tz
2025-06-12 10:24:28,869 [INFO] Registrada tentativa de login: username=admin, IP=127.0.0.1, Maliciosa=True
2025-06-12 10:24:29,637 [INFO] Usuário admin acessando página inicial
2025-06-12 10:24:29,643 [INFO] Dados setores: {'labels': ['Admin'], 'data': [1]}
2025-06-12 10:24:29,645 [DEBUG] Usuário admin - Tipo: master_admin, Pode ver: True
2025-06-12 10:24:30,461 [DEBUG] Processando requisição para /participacao/participacao/ - Usuário autenticado: True
2025-06-12 10:24:30,464 [INFO] Usuário admin acessando participação
2025-06-12 10:24:30,464 [DEBUG] Último trimestre: 2025-Q2
2025-06-12 10:24:30,479 [DEBUG] Dados enviados: page_obj=[]
2025-06-12 10:24:30,558 [ERROR] Internal Server Error: /participacao/participacao/
Traceback (most recent call last):
  File "C:\Users\adm1t\AppData\Local\Programs\Python\Python312\Lib\site-packages\django\core\handlers\exception.py", line 55, in inner
    response = get_response(request)
               ^^^^^^^^^^^^^^^^^^^^^
  File "C:\Users\adm1t\AppData\Local\Programs\Python\Python312\Lib\site-packages\django\core\handlers\base.py", line 197, in _get_response
    response = wrapped_callback(request, *callback_args, **callback_kwargs)
               ^^^^^^^^^^^^^^^^^^^^^^^^^^^^^^^^^^^^^^^^^^^^^^^^^^^^^^^^^^^^
  File "C:\Users\adm1t\AppData\Local\Programs\Python\Python312\Lib\site-packages\django\contrib\auth\decorators.py", line 59, in _view_wrapper
    return view_func(request, *args, **kwargs)
           ^^^^^^^^^^^^^^^^^^^^^^^^^^^^^^^^^^^
  File "C:\Users\adm1t\Desktop\Projeto_Portal\Projeto_Portal_v2_trabalho\Migracao_Portal_v2\apps\participacao\decorators.py", line 21, in wrapper
    return view_func(request, *args, **kwargs)
           ^^^^^^^^^^^^^^^^^^^^^^^^^^^^^^^^^^^
  File "C:\Users\adm1t\Desktop\Projeto_Portal\Projeto_Portal_v2_trabalho\Migracao_Portal_v2\apps\participacao\views\participation.py", line 876, in participacao
    return render(request, 'participacao/participacao.html', {
           ^^^^^^^^^^^^^^^^^^^^^^^^^^^^^^^^^^^^^^^^^^^^^^^^^^^
  File "C:\Users\adm1t\AppData\Local\Programs\Python\Python312\Lib\site-packages\django\shortcuts.py", line 25, in render
    content = loader.render_to_string(template_name, context, request, using=using)
              ^^^^^^^^^^^^^^^^^^^^^^^^^^^^^^^^^^^^^^^^^^^^^^^^^^^^^^^^^^^^^^^^^^^^^
  File "C:\Users\adm1t\AppData\Local\Programs\Python\Python312\Lib\site-packages\django\template\loader.py", line 61, in render_to_string
    template = get_template(template_name, using=using)
               ^^^^^^^^^^^^^^^^^^^^^^^^^^^^^^^^^^^^^^^^
  File "C:\Users\adm1t\AppData\Local\Programs\Python\Python312\Lib\site-packages\django\template\loader.py", line 15, in get_template
    return engine.get_template(template_name)
           ^^^^^^^^^^^^^^^^^^^^^^^^^^^^^^^^^^
  File "C:\Users\adm1t\AppData\Local\Programs\Python\Python312\Lib\site-packages\django\template\backends\django.py", line 79, in get_template
    return Template(self.engine.get_template(template_name), self)
                    ^^^^^^^^^^^^^^^^^^^^^^^^^^^^^^^^^^^^^^^
  File "C:\Users\adm1t\AppData\Local\Programs\Python\Python312\Lib\site-packages\django\template\engine.py", line 177, in get_template
    template, origin = self.find_template(template_name)
                       ^^^^^^^^^^^^^^^^^^^^^^^^^^^^^^^^^
  File "C:\Users\adm1t\AppData\Local\Programs\Python\Python312\Lib\site-packages\django\template\engine.py", line 159, in find_template
    template = loader.get_template(name, skip=skip)
               ^^^^^^^^^^^^^^^^^^^^^^^^^^^^^^^^^^^^
  File "C:\Users\adm1t\AppData\Local\Programs\Python\Python312\Lib\site-packages\django\template\loaders\cached.py", line 57, in get_template
    template = super().get_template(template_name, skip)
               ^^^^^^^^^^^^^^^^^^^^^^^^^^^^^^^^^^^^^^^^^
  File "C:\Users\adm1t\AppData\Local\Programs\Python\Python312\Lib\site-packages\django\template\loaders\base.py", line 28, in get_template
    return Template(
           ^^^^^^^^^
  File "C:\Users\adm1t\AppData\Local\Programs\Python\Python312\Lib\site-packages\django\template\base.py", line 154, in __init__
    self.nodelist = self.compile_nodelist()
                    ^^^^^^^^^^^^^^^^^^^^^^^
  File "C:\Users\adm1t\AppData\Local\Programs\Python\Python312\Lib\site-packages\django\template\base.py", line 196, in compile_nodelist
    nodelist = parser.parse()
               ^^^^^^^^^^^^^^
  File "C:\Users\adm1t\AppData\Local\Programs\Python\Python312\Lib\site-packages\django\template\base.py", line 518, in parse
    raise self.error(token, e)
  File "C:\Users\adm1t\AppData\Local\Programs\Python\Python312\Lib\site-packages\django\template\base.py", line 516, in parse
    compiled_result = compile_func(self, token)
                      ^^^^^^^^^^^^^^^^^^^^^^^^^
  File "C:\Users\adm1t\AppData\Local\Programs\Python\Python312\Lib\site-packages\django\template\defaulttags.py", line 962, in do_if
    nodelist = parser.parse(("elif", "else", "endif"))
               ^^^^^^^^^^^^^^^^^^^^^^^^^^^^^^^^^^^^^^^
  File "C:\Users\adm1t\AppData\Local\Programs\Python\Python312\Lib\site-packages\django\template\base.py", line 489, in parse
    raise self.error(token, e)
  File "C:\Users\adm1t\AppData\Local\Programs\Python\Python312\Lib\site-packages\django\template\base.py", line 487, in parse
    filter_expression = self.compile_filter(token.contents)
                        ^^^^^^^^^^^^^^^^^^^^^^^^^^^^^^^^^^^
  File "C:\Users\adm1t\AppData\Local\Programs\Python\Python312\Lib\site-packages\django\template\base.py", line 609, in compile_filter
    return FilterExpression(token, self)
           ^^^^^^^^^^^^^^^^^^^^^^^^^^^^^
  File "C:\Users\adm1t\AppData\Local\Programs\Python\Python312\Lib\site-packages\django\template\base.py", line 705, in __init__
    filter_func = parser.find_filter(filter_name)
                  ^^^^^^^^^^^^^^^^^^^^^^^^^^^^^^^
  File "C:\Users\adm1t\AppData\Local\Programs\Python\Python312\Lib\site-packages\django\template\base.py", line 615, in find_filter
    raise TemplateSyntaxError("Invalid filter: '%s'" % filter_name)
django.template.exceptions.TemplateSyntaxError: Invalid filter: 'format_currency'
2025-06-12 10:28:33,788 [INFO] Registrada tentativa de login: username=admin, IP=127.0.0.1, Maliciosa=True
2025-06-12 10:28:34,524 [INFO] Usuário admin acessando página inicial
2025-06-12 10:28:34,530 [INFO] Dados setores: {'labels': ['Admin'], 'data': [1]}
2025-06-12 10:28:34,532 [DEBUG] Usuário admin - Tipo: master_admin, Pode ver: True
2025-06-12 10:28:35,673 [DEBUG] Processando requisição para /participacao/participacao/ - Usuário autenticado: True
2025-06-12 10:28:35,676 [INFO] Usuário admin acessando participação
2025-06-12 10:28:35,678 [DEBUG] Último trimestre: 2025-Q2
2025-06-12 10:28:35,689 [DEBUG] Dados enviados: page_obj=[]
2025-06-12 10:28:35,776 [ERROR] Internal Server Error: /participacao/participacao/
Traceback (most recent call last):
  File "C:\Users\adm1t\AppData\Local\Programs\Python\Python312\Lib\site-packages\django\core\handlers\exception.py", line 55, in inner
    response = get_response(request)
               ^^^^^^^^^^^^^^^^^^^^^
  File "C:\Users\adm1t\AppData\Local\Programs\Python\Python312\Lib\site-packages\django\core\handlers\base.py", line 197, in _get_response
    response = wrapped_callback(request, *callback_args, **callback_kwargs)
               ^^^^^^^^^^^^^^^^^^^^^^^^^^^^^^^^^^^^^^^^^^^^^^^^^^^^^^^^^^^^
  File "C:\Users\adm1t\AppData\Local\Programs\Python\Python312\Lib\site-packages\django\contrib\auth\decorators.py", line 59, in _view_wrapper
    return view_func(request, *args, **kwargs)
           ^^^^^^^^^^^^^^^^^^^^^^^^^^^^^^^^^^^
  File "C:\Users\adm1t\Desktop\Projeto_Portal\Projeto_Portal_v2_trabalho\Migracao_Portal_v2\apps\participacao\decorators.py", line 21, in wrapper
    return view_func(request, *args, **kwargs)
           ^^^^^^^^^^^^^^^^^^^^^^^^^^^^^^^^^^^
  File "C:\Users\adm1t\Desktop\Projeto_Portal\Projeto_Portal_v2_trabalho\Migracao_Portal_v2\apps\participacao\views\participation.py", line 876, in participacao
    return render(request, 'participacao/participacao.html', {
           ^^^^^^^^^^^^^^^^^^^^^^^^^^^^^^^^^^^^^^^^^^^^^^^^^^^
  File "C:\Users\adm1t\AppData\Local\Programs\Python\Python312\Lib\site-packages\django\shortcuts.py", line 25, in render
    content = loader.render_to_string(template_name, context, request, using=using)
              ^^^^^^^^^^^^^^^^^^^^^^^^^^^^^^^^^^^^^^^^^^^^^^^^^^^^^^^^^^^^^^^^^^^^^
  File "C:\Users\adm1t\AppData\Local\Programs\Python\Python312\Lib\site-packages\django\template\loader.py", line 61, in render_to_string
    template = get_template(template_name, using=using)
               ^^^^^^^^^^^^^^^^^^^^^^^^^^^^^^^^^^^^^^^^
  File "C:\Users\adm1t\AppData\Local\Programs\Python\Python312\Lib\site-packages\django\template\loader.py", line 15, in get_template
    return engine.get_template(template_name)
           ^^^^^^^^^^^^^^^^^^^^^^^^^^^^^^^^^^
  File "C:\Users\adm1t\AppData\Local\Programs\Python\Python312\Lib\site-packages\django\template\backends\django.py", line 79, in get_template
    return Template(self.engine.get_template(template_name), self)
                    ^^^^^^^^^^^^^^^^^^^^^^^^^^^^^^^^^^^^^^^
  File "C:\Users\adm1t\AppData\Local\Programs\Python\Python312\Lib\site-packages\django\template\engine.py", line 177, in get_template
    template, origin = self.find_template(template_name)
                       ^^^^^^^^^^^^^^^^^^^^^^^^^^^^^^^^^
  File "C:\Users\adm1t\AppData\Local\Programs\Python\Python312\Lib\site-packages\django\template\engine.py", line 159, in find_template
    template = loader.get_template(name, skip=skip)
               ^^^^^^^^^^^^^^^^^^^^^^^^^^^^^^^^^^^^
  File "C:\Users\adm1t\AppData\Local\Programs\Python\Python312\Lib\site-packages\django\template\loaders\cached.py", line 57, in get_template
    template = super().get_template(template_name, skip)
               ^^^^^^^^^^^^^^^^^^^^^^^^^^^^^^^^^^^^^^^^^
  File "C:\Users\adm1t\AppData\Local\Programs\Python\Python312\Lib\site-packages\django\template\loaders\base.py", line 28, in get_template
    return Template(
           ^^^^^^^^^
  File "C:\Users\adm1t\AppData\Local\Programs\Python\Python312\Lib\site-packages\django\template\base.py", line 154, in __init__
    self.nodelist = self.compile_nodelist()
                    ^^^^^^^^^^^^^^^^^^^^^^^
  File "C:\Users\adm1t\AppData\Local\Programs\Python\Python312\Lib\site-packages\django\template\base.py", line 196, in compile_nodelist
    nodelist = parser.parse()
               ^^^^^^^^^^^^^^
  File "C:\Users\adm1t\AppData\Local\Programs\Python\Python312\Lib\site-packages\django\template\base.py", line 518, in parse
    raise self.error(token, e)
  File "C:\Users\adm1t\AppData\Local\Programs\Python\Python312\Lib\site-packages\django\template\base.py", line 516, in parse
    compiled_result = compile_func(self, token)
                      ^^^^^^^^^^^^^^^^^^^^^^^^^
  File "C:\Users\adm1t\AppData\Local\Programs\Python\Python312\Lib\site-packages\django\template\defaulttags.py", line 862, in do_for
    nodelist_loop = parser.parse(
                    ^^^^^^^^^^^^^
  File "C:\Users\adm1t\AppData\Local\Programs\Python\Python312\Lib\site-packages\django\template\base.py", line 518, in parse
    raise self.error(token, e)
  File "C:\Users\adm1t\AppData\Local\Programs\Python\Python312\Lib\site-packages\django\template\base.py", line 516, in parse
    compiled_result = compile_func(self, token)
                      ^^^^^^^^^^^^^^^^^^^^^^^^^
  File "C:\Users\adm1t\AppData\Local\Programs\Python\Python312\Lib\site-packages\django\template\defaulttags.py", line 962, in do_if
    nodelist = parser.parse(("elif", "else", "endif"))
               ^^^^^^^^^^^^^^^^^^^^^^^^^^^^^^^^^^^^^^^
  File "C:\Users\adm1t\AppData\Local\Programs\Python\Python312\Lib\site-packages\django\template\base.py", line 518, in parse
    raise self.error(token, e)
  File "C:\Users\adm1t\AppData\Local\Programs\Python\Python312\Lib\site-packages\django\template\base.py", line 516, in parse
    compiled_result = compile_func(self, token)
                      ^^^^^^^^^^^^^^^^^^^^^^^^^
  File "C:\Users\adm1t\AppData\Local\Programs\Python\Python312\Lib\site-packages\django\template\defaulttags.py", line 1531, in do_with
    extra_context = token_kwargs(remaining_bits, parser, support_legacy=True)
                    ^^^^^^^^^^^^^^^^^^^^^^^^^^^^^^^^^^^^^^^^^^^^^^^^^^^^^^^^^
  File "C:\Users\adm1t\AppData\Local\Programs\Python\Python312\Lib\site-packages\django\template\base.py", line 1127, in token_kwargs
    kwargs[key] = parser.compile_filter(value)
                  ^^^^^^^^^^^^^^^^^^^^^^^^^^^^
  File "C:\Users\adm1t\AppData\Local\Programs\Python\Python312\Lib\site-packages\django\template\base.py", line 609, in compile_filter
    return FilterExpression(token, self)
           ^^^^^^^^^^^^^^^^^^^^^^^^^^^^^
  File "C:\Users\adm1t\AppData\Local\Programs\Python\Python312\Lib\site-packages\django\template\base.py", line 705, in __init__
    filter_func = parser.find_filter(filter_name)
                  ^^^^^^^^^^^^^^^^^^^^^^^^^^^^^^^
  File "C:\Users\adm1t\AppData\Local\Programs\Python\Python312\Lib\site-packages\django\template\base.py", line 615, in find_filter
    raise TemplateSyntaxError("Invalid filter: '%s'" % filter_name)
django.template.exceptions.TemplateSyntaxError: Invalid filter: 'json_parse'
2025-06-12 10:36:58,179 [INFO] Registrada tentativa de login: username=admin, IP=127.0.0.1, Maliciosa=True
2025-06-12 10:36:58,917 [INFO] Usuário admin acessando página inicial
2025-06-12 10:36:58,923 [INFO] Dados setores: {'labels': ['Admin'], 'data': [1]}
2025-06-12 10:36:58,924 [DEBUG] Usuário admin - Tipo: master_admin, Pode ver: True
2025-06-12 10:36:59,841 [DEBUG] Processando requisição para /participacao/participacao/ - Usuário autenticado: True
2025-06-12 10:36:59,847 [INFO] Usuário admin acessando participação
2025-06-12 10:36:59,848 [DEBUG] Último trimestre: 2025-Q2
2025-06-12 10:36:59,862 [DEBUG] Dados enviados: page_obj=[]
2025-06-12 10:36:59,955 [ERROR] Internal Server Error: /participacao/participacao/
Traceback (most recent call last):
  File "C:\Users\adm1t\AppData\Local\Programs\Python\Python312\Lib\site-packages\django\core\handlers\exception.py", line 55, in inner
    response = get_response(request)
               ^^^^^^^^^^^^^^^^^^^^^
  File "C:\Users\adm1t\AppData\Local\Programs\Python\Python312\Lib\site-packages\django\core\handlers\base.py", line 197, in _get_response
    response = wrapped_callback(request, *callback_args, **callback_kwargs)
               ^^^^^^^^^^^^^^^^^^^^^^^^^^^^^^^^^^^^^^^^^^^^^^^^^^^^^^^^^^^^
  File "C:\Users\adm1t\AppData\Local\Programs\Python\Python312\Lib\site-packages\django\contrib\auth\decorators.py", line 59, in _view_wrapper
    return view_func(request, *args, **kwargs)
           ^^^^^^^^^^^^^^^^^^^^^^^^^^^^^^^^^^^
  File "C:\Users\adm1t\Desktop\Projeto_Portal\Projeto_Portal_v2_trabalho\Migracao_Portal_v2\apps\participacao\decorators.py", line 21, in wrapper
    return view_func(request, *args, **kwargs)
           ^^^^^^^^^^^^^^^^^^^^^^^^^^^^^^^^^^^
  File "C:\Users\adm1t\Desktop\Projeto_Portal\Projeto_Portal_v2_trabalho\Migracao_Portal_v2\apps\participacao\views\participation.py", line 876, in participacao
    return render(request, 'participacao/participacao.html', {
           ^^^^^^^^^^^^^^^^^^^^^^^^^^^^^^^^^^^^^^^^^^^^^^^^^^^
  File "C:\Users\adm1t\AppData\Local\Programs\Python\Python312\Lib\site-packages\django\shortcuts.py", line 25, in render
    content = loader.render_to_string(template_name, context, request, using=using)
              ^^^^^^^^^^^^^^^^^^^^^^^^^^^^^^^^^^^^^^^^^^^^^^^^^^^^^^^^^^^^^^^^^^^^^
  File "C:\Users\adm1t\AppData\Local\Programs\Python\Python312\Lib\site-packages\django\template\loader.py", line 62, in render_to_string
    return template.render(context, request)
           ^^^^^^^^^^^^^^^^^^^^^^^^^^^^^^^^^
  File "C:\Users\adm1t\AppData\Local\Programs\Python\Python312\Lib\site-packages\django\template\backends\django.py", line 107, in render
    return self.template.render(context)
           ^^^^^^^^^^^^^^^^^^^^^^^^^^^^^
  File "C:\Users\adm1t\AppData\Local\Programs\Python\Python312\Lib\site-packages\django\template\base.py", line 171, in render
    return self._render(context)
           ^^^^^^^^^^^^^^^^^^^^^
  File "C:\Users\adm1t\AppData\Local\Programs\Python\Python312\Lib\site-packages\django\template\base.py", line 163, in _render
    return self.nodelist.render(context)
           ^^^^^^^^^^^^^^^^^^^^^^^^^^^^^
  File "C:\Users\adm1t\AppData\Local\Programs\Python\Python312\Lib\site-packages\django\template\base.py", line 1016, in render
    return SafeString("".join([node.render_annotated(context) for node in self]))
                               ^^^^^^^^^^^^^^^^^^^^^^^^^^^^^^
  File "C:\Users\adm1t\AppData\Local\Programs\Python\Python312\Lib\site-packages\django\template\base.py", line 977, in render_annotated
    return self.render(context)
           ^^^^^^^^^^^^^^^^^^^^
  File "C:\Users\adm1t\AppData\Local\Programs\Python\Python312\Lib\site-packages\django\template\defaulttags.py", line 327, in render
    return nodelist.render(context)
           ^^^^^^^^^^^^^^^^^^^^^^^^
  File "C:\Users\adm1t\AppData\Local\Programs\Python\Python312\Lib\site-packages\django\template\base.py", line 1016, in render
    return SafeString("".join([node.render_annotated(context) for node in self]))
                               ^^^^^^^^^^^^^^^^^^^^^^^^^^^^^^
  File "C:\Users\adm1t\AppData\Local\Programs\Python\Python312\Lib\site-packages\django\template\base.py", line 977, in render_annotated
    return self.render(context)
           ^^^^^^^^^^^^^^^^^^^^
  File "C:\Users\adm1t\AppData\Local\Programs\Python\Python312\Lib\site-packages\django\template\defaulttags.py", line 327, in render
    return nodelist.render(context)
           ^^^^^^^^^^^^^^^^^^^^^^^^
  File "C:\Users\adm1t\AppData\Local\Programs\Python\Python312\Lib\site-packages\django\template\base.py", line 1016, in render
    return SafeString("".join([node.render_annotated(context) for node in self]))
                               ^^^^^^^^^^^^^^^^^^^^^^^^^^^^^^
  File "C:\Users\adm1t\AppData\Local\Programs\Python\Python312\Lib\site-packages\django\template\base.py", line 977, in render_annotated
    return self.render(context)
           ^^^^^^^^^^^^^^^^^^^^
  File "C:\Users\adm1t\AppData\Local\Programs\Python\Python312\Lib\site-packages\django\template\defaulttags.py", line 480, in render
    url = reverse(view_name, args=args, kwargs=kwargs, current_app=current_app)
          ^^^^^^^^^^^^^^^^^^^^^^^^^^^^^^^^^^^^^^^^^^^^^^^^^^^^^^^^^^^^^^^^^^^^^
  File "C:\Users\adm1t\AppData\Local\Programs\Python\Python312\Lib\site-packages\django\urls\base.py", line 98, in reverse
    resolved_url = resolver._reverse_with_prefix(view, prefix, *args, **kwargs)
                   ^^^^^^^^^^^^^^^^^^^^^^^^^^^^^^^^^^^^^^^^^^^^^^^^^^^^^^^^^^^^
  File "C:\Users\adm1t\AppData\Local\Programs\Python\Python312\Lib\site-packages\django\urls\resolvers.py", line 831, in _reverse_with_prefix
    raise NoReverseMatch(msg)
django.urls.exceptions.NoReverseMatch: Reverse for 'logs' with no arguments not found. 1 pattern(s) tried: ['participacao/logs/(?P<funcionario_id>[0-9]+)/\\Z']
2025-06-12 10:41:06,639 [INFO] Registrada tentativa de login: username=admin, IP=127.0.0.1, Maliciosa=True
2025-06-12 10:41:07,376 [INFO] Usuário admin acessando página inicial
2025-06-12 10:41:07,380 [INFO] Dados setores: {'labels': ['Admin'], 'data': [1]}
2025-06-12 10:41:07,382 [DEBUG] Usuário admin - Tipo: master_admin, Pode ver: True
2025-06-12 10:41:08,393 [DEBUG] Processando requisição para /participacao/participacao/ - Usuário autenticado: True
2025-06-12 10:41:08,397 [INFO] Usuário admin acessando participação
2025-06-12 10:41:08,398 [DEBUG] Último trimestre: 2025-Q2
2025-06-12 10:41:08,411 [DEBUG] Dados enviados: page_obj=[]
2025-06-12 10:41:16,093 [DEBUG] Processando requisição para /participacao/importar_planilha_participacao/ - Usuário autenticado: True
2025-06-12 10:41:16,211 [DEBUG] Processando requisição para /participacao/participacao/ - Usuário autenticado: True
2025-06-12 10:41:16,216 [INFO] Usuário admin acessando participação
2025-06-12 10:41:16,217 [DEBUG] Último trimestre: 2025-Q2
2025-06-12 10:41:16,228 [DEBUG] Dados enviados: page_obj=[]
2025-06-12 10:41:19,112 [DEBUG] Processando requisição para /participacao/importar_planilha_participacao/ - Usuário autenticado: True
2025-06-12 10:41:19,226 [DEBUG] Processando requisição para /participacao/participacao/ - Usuário autenticado: True
2025-06-12 10:41:19,228 [INFO] Usuário admin acessando participação
2025-06-12 10:41:19,228 [DEBUG] Último trimestre: 2025-Q2
2025-06-12 10:41:19,237 [DEBUG] Dados enviados: page_obj=[]
2025-06-12 10:47:50,047 [INFO] C:\Users\adm1t\Desktop\Projeto_Portal\Projeto_Portal_v2_trabalho\Migracao_Portal_v2\apps\participacao\views\participation.py changed, reloading.
2025-06-12 10:49:10,349 [INFO] Registrada tentativa de login: username=admin, IP=127.0.0.1, Maliciosa=True
2025-06-12 10:49:11,197 [INFO] Usuário admin acessando página inicial
2025-06-12 10:49:11,204 [INFO] Dados setores: {'labels': ['Admin'], 'data': [1]}
2025-06-12 10:49:11,206 [DEBUG] Usuário admin - Tipo: master_admin, Pode ver: True
2025-06-12 10:49:12,884 [DEBUG] Processando requisição para /participacao/participacao/ - Usuário autenticado: True
2025-06-12 10:49:12,887 [INFO] Usuário admin acessando participação
2025-06-12 10:49:12,887 [DEBUG] Último trimestre: 2025-Q2
2025-06-12 10:49:12,903 [DEBUG] Dados enviados: page_obj=[]
2025-06-12 10:49:14,567 [DEBUG] Processando requisição para /participacao/importar_planilha_participacao/ - Usuário autenticado: True
2025-06-12 10:49:14,611 [ERROR] Internal Server Error: /participacao/importar_planilha_participacao/
Traceback (most recent call last):
  File "C:\Users\adm1t\AppData\Local\Programs\Python\Python312\Lib\site-packages\django\core\handlers\exception.py", line 55, in inner
    response = get_response(request)
               ^^^^^^^^^^^^^^^^^^^^^
  File "C:\Users\adm1t\AppData\Local\Programs\Python\Python312\Lib\site-packages\django\core\handlers\base.py", line 197, in _get_response
    response = wrapped_callback(request, *callback_args, **callback_kwargs)
               ^^^^^^^^^^^^^^^^^^^^^^^^^^^^^^^^^^^^^^^^^^^^^^^^^^^^^^^^^^^^
  File "C:\Users\adm1t\AppData\Local\Programs\Python\Python312\Lib\site-packages\django\contrib\auth\decorators.py", line 59, in _view_wrapper
    return view_func(request, *args, **kwargs)
           ^^^^^^^^^^^^^^^^^^^^^^^^^^^^^^^^^^^
  File "C:\Users\adm1t\Desktop\Projeto_Portal\Projeto_Portal_v2_trabalho\Migracao_Portal_v2\apps\participacao\decorators.py", line 21, in wrapper
    return view_func(request, *args, **kwargs)
           ^^^^^^^^^^^^^^^^^^^^^^^^^^^^^^^^^^^
  File "C:\Users\adm1t\Desktop\Projeto_Portal\Projeto_Portal_v2_trabalho\Migracao_Portal_v2\apps\participacao\views\participation.py", line 1042, in importar_planilha_participacao
    form = PlanilhaParticipacaoForm()
           ^^^^^^^^^^^^^^^^^^^^^^^^
NameError: name 'PlanilhaParticipacaoForm' is not defined
2025-06-12 10:50:45,742 [INFO] C:\Users\adm1t\Desktop\Projeto_Portal\Projeto_Portal_v2_trabalho\Migracao_Portal_v2\apps\participacao\views\participation.py changed, reloading.
2025-06-12 10:50:57,842 [INFO] Registrada tentativa de login: username=admin, IP=127.0.0.1, Maliciosa=True
2025-06-12 10:50:58,559 [INFO] Usuário admin acessando página inicial
2025-06-12 10:50:58,563 [INFO] Dados setores: {'labels': ['Admin'], 'data': [1]}
2025-06-12 10:50:58,564 [DEBUG] Usuário admin - Tipo: master_admin, Pode ver: True
2025-06-12 10:50:59,537 [DEBUG] Processando requisição para /participacao/participacao/ - Usuário autenticado: True
2025-06-12 10:50:59,540 [INFO] Usuário admin acessando participação
2025-06-12 10:50:59,542 [DEBUG] Último trimestre: 2025-Q2
2025-06-12 10:50:59,556 [DEBUG] Dados enviados: page_obj=[]
2025-06-12 10:51:00,806 [DEBUG] Processando requisição para /participacao/importar_planilha_participacao/ - Usuário autenticado: True
2025-06-12 10:51:00,852 [ERROR] Internal Server Error: /participacao/importar_planilha_participacao/
Traceback (most recent call last):
  File "C:\Users\adm1t\AppData\Local\Programs\Python\Python312\Lib\site-packages\django\core\handlers\exception.py", line 55, in inner
    response = get_response(request)
               ^^^^^^^^^^^^^^^^^^^^^
  File "C:\Users\adm1t\AppData\Local\Programs\Python\Python312\Lib\site-packages\django\core\handlers\base.py", line 197, in _get_response
    response = wrapped_callback(request, *callback_args, **callback_kwargs)
               ^^^^^^^^^^^^^^^^^^^^^^^^^^^^^^^^^^^^^^^^^^^^^^^^^^^^^^^^^^^^
  File "C:\Users\adm1t\AppData\Local\Programs\Python\Python312\Lib\site-packages\django\contrib\auth\decorators.py", line 59, in _view_wrapper
    return view_func(request, *args, **kwargs)
           ^^^^^^^^^^^^^^^^^^^^^^^^^^^^^^^^^^^
  File "C:\Users\adm1t\Desktop\Projeto_Portal\Projeto_Portal_v2_trabalho\Migracao_Portal_v2\apps\participacao\decorators.py", line 21, in wrapper
    return view_func(request, *args, **kwargs)
           ^^^^^^^^^^^^^^^^^^^^^^^^^^^^^^^^^^^
  File "C:\Users\adm1t\Desktop\Projeto_Portal\Projeto_Portal_v2_trabalho\Migracao_Portal_v2\apps\participacao\views\participation.py", line 1047, in importar_planilha_participacao
    form = PlanilhaParticipacaoForm()
           ^^^^^^^^^^^^^^^^^^^^^^^^
NameError: name 'PlanilhaParticipacaoForm' is not defined
2025-06-12 10:52:58,586 [INFO] C:\Users\adm1t\Desktop\Projeto_Portal\Projeto_Portal_v2_trabalho\Migracao_Portal_v2\apps\participacao\views\participation.py changed, reloading.
2025-06-12 10:53:16,851 [INFO] C:\Users\adm1t\Desktop\Projeto_Portal\Projeto_Portal_v2_trabalho\Migracao_Portal_v2\apps\participacao\views\participation.py changed, reloading.
2025-06-12 10:56:17,057 [INFO] C:\Users\adm1t\Desktop\Projeto_Portal\Projeto_Portal_v2_trabalho\Migracao_Portal_v2\apps\participacao\views\participation.py changed, reloading.
2025-06-12 10:58:20,984 [INFO] C:\Users\adm1t\Desktop\Projeto_Portal\Projeto_Portal_v2_trabalho\Migracao_Portal_v2\apps\participacao\forms.py changed, reloading.
2025-06-12 11:01:11,062 [INFO] C:\Users\adm1t\Desktop\Projeto_Portal\Projeto_Portal_v2_trabalho\Migracao_Portal_v2\apps\participacao\models\__init__.py changed, reloading.
2025-06-12 11:01:31,659 [INFO] C:\Users\adm1t\Desktop\Projeto_Portal\Projeto_Portal_v2_trabalho\Migracao_Portal_v2\apps\participacao\models\__init__.py changed, reloading.
